Workbook
Name 报价本: #REF!

Sheet 目录
A2: 序号 | B2: 产品名称 | C2: 价格详情 | E2: 渠道和目的港 | F2: 线路特点
A3: 1 | B3: 船期表 | C3: 点击进入
A4: 2 | B4: 美国海派包税 | C4: 点击进入 | E4: 长滩和纽约 美森CLX CLX+ 限时达统配 OA普船 | F4: 双清 包税 尾程：UPS或者FEDEX，五截三开，适合纸箱散货，时效：16-18个工作日提取
A5: 3 | B5: 美国亚马逊仓库特价 | C5: 点击进入 | E5: 长滩/休斯顿/芝加哥/纽约/萨凡纳
B6: 美西OA普船美转墨卡派 | C6: 点击进入 | E6: 美西OA普船（COSCO CMA OOCL EMC ZIM) | F6: 双清 包税 尾程：卡派 五截三开，16天左右提柜
A7: 4 | B7: 美森至尊达-卡派 | C7: 点击进入 | E7: 美森正班船CLX 长滩 | F7: 双清 包税 尾程：卡派 五截三开，时效稳定，12天左右提柜
A8: 5 | B8: 美森限时达-卡派 | C8: 点击进入 | E8: 美森加班船MAX 长滩 | F8: 双清 包税 尾程：卡派 五截四开，时效稳定，14天左右提柜
A9: 6 | B9: 限时达统配卡派 | C9: 点击进人 | E9: 合德快提/EXX/COSCO美速达快卸快提 (LOS ANGELES拆柜） | F9: 双清 包税 尾程：卡派 五截三开，开船之后14天提柜，普船的价格，美森的时效
A10: 7 | B10: 限时达统配美转加FBA卡车 | C10: 点击进入 | E10: 合德快提/EXX/COSCO美速达快卸快提 (LOS ANGELES拆柜） | F10: 双清 包税 尾程：卡派 五截三开，开船之后14天提柜
A11: 8 | B11: 限时达统配美转加非FBA卡车 | C11: 点击进入 | E11: 合德快提/EXX/COSCO美速达快卸快提 (LOS ANGELES拆柜） | F11: 双清 包税 尾程：卡派 五截三开，开船之后14天提柜
A12: 9 | B12: 美西OA普船卡派 | C12: 点击进入 | E12: 美西OA普船（COSCO CMA OOCL EMC ZIM) | F12: 双清 包税 尾程：卡派 五截三开，16天左右提柜
A13: 10 | B13: 美线商业卡车 | C13: 点击进入 | E13: 从我司CA 91761仓库送40 MILES以内商业地址 | F13: 双清 包税 尾程：卡派
A14: 11 | B14: 美东NY普船卡车 | C14: 点击进入 | E14: 纽约拆 | F14: 双清 包税 尾程：卡派，26天左右到港，时效稳定
A15: 12 | B15: 美东SAV普船卡车 | C15: 点击进入 | E15: 萨凡纳拆 | F15: 双清 包税 尾程：卡派，30天左右到港，时效稳定
A16: 13 | B16: 空运特快专线 | C16: 点击进入 | E16: 上海统配 LAX ORD JFK | F16: 双清 包税 尾程：UPS或者FEDEX，每周3-4个航班，进仓之后2天左右飞走，适合：散货 托盘 时效：3-5个工作日提取
A17: 14 | B17: 加拿大TOR商卡分区表 | C17: 点击进入
A18: 15 | B18: 加拿大CAL商卡分区表 | C18: 点击进入
A19: 16 | B19: UPS偏远地址表 | C19: 详细资料
A20: 17 | B20: 美国加征关税列表 | C20: 详细资料
A21: 18 | B21: 禁运反倾销及特殊监管表 | C21: 详细资料
A22: 19 | B22: 反倾销目录 | C22: 详细资料
A23: 20 | B23: 美国关税232钢铝铜HS表格 | C23: 详细资料
A24: 21 | B24: FBA仓库地址表 | C24: 详细资料

Sheet 船期表
A6: 渠道名称 | B6: 船名航次 | C6: 船期 | D6: 截单时间 | E6: 截货时间（上海/义乌/宁波仓库） | F6: 截货时间（青岛仓库） | G6: 截货时间（深圳仓库）
A7: 美西OA/ZIM普船 | B7: CSCL SOUTH CHINA SEA 083E | C7: 46200 | D7: 46191 | E7: 46194 | F7: 46192 | G7: 46192 | H7: 注意：义乌仓库6/19号休息不收货。
A8: 限时达统配美转加 | B8: PORTO 2606E | C8: 46198 | D8: 46191 | E8: 46194 | F8: 46192 | G8: 46192
A9: 限时达统配 | B9: PORTO 2606E | C9: 46198 | D9: 46191 | E9: 46194 | F9: 46192 | G9: 46192
A10: 美东NY普船 | B10: COSCO SHIPPING ORCHID 034E | C10: 46199 | D10: 46191 | E10: 46194 | F10: 46192 | G10: 46192
A11: 美东SAV普船 | B11: COSCO SHIPPING ORCHID 034E | C11: 46199 | D11: 46191 | E11: 46194 | F11: 46192 | G11: 46192
A12: 芝加哥普船 | B12: CSCL SOUTH CHINA SEA 083E | C12: 46200 | D12: 46191 | E12: 46194 | F12: 46192 | G12: 46192
A13: 休斯顿普船 | B13: 不固定 | C13: 46197 | D13: 46191 | E13: 46194 | F13: 46192 | G13: 46192
A14: 美西OA普船美转墨卡派 | B14: CSCL SOUTH CHINA SEA 083E | C14: 46200 | D14: 46191 | E14: 46194 | F14: 46192 | G14: 46192
A15: 美森至尊达 | B15: MATSON WAIKIKI 026E | C15: 46197 | D15: 46191 | E15: 46194 | F15: 46192 | G15: 46192
A16: 美森限时达 | B16: MANUKAI 257E | C16: 46198 | D16: 46191 | E16: 46194 | F16: 46192 | G16: 46192

Sheet 美国海派包税
A7: 美森至尊达（美森正班船CLX） | N7: 船期：06月24日 | O7: 返回目录
A8: 区域 | C8: 重量 | D8: 12-70 | E8: 71-99 | F8: 100+ | G8: 签收时效（自然日） | H8: 预计提取时间 | K8: 截单时间 | L8: 最晚进仓时间 | M8: 开船时间 | N8: 备注
A9: 美东 (邮编0.1.2.3开头) | C9: 价格 | D9: =F9+6 -> 21.5 | E9: =F9+3 -> 18.5 | F9: 15.5 | G9: 17-18天 | H9: 开船后15天提取-晚一天赔1元/KG，最高赔付3元/KG.(如遇节假日、海关查验、码头停摆、罢工等不可抗拒因素除外） | K9: 周五 | L9: 周日 | M9: 周三 | N9: 1,比重1：200 价格本减0.5/KG 1:300价格本减1/KG （比重只适用于100KG以上的货物） 2,单件最低计费重量12KG,单件不足12KGS按12KGS计费，抛货体积除以6000. 3，单独报关200/票，买单免收报关费 4，系统下单渠道：美森至尊达
A10: 美中 (邮编4.5.6.7开头) | C10: 价格 | D10: =F10+6 -> 20.5 | E10: =F10+3 -> 17.5 | F10: 14.5 | G10: 15-16天
A11: 美西(邮编8.9开头) | C11: 价格 | D11: =F11+6 -> 19 | E11: =F11+3 -> 16 | F11: 13 | G11: 13-14天
A12: 美森限时达（美森加班船MAX） | N12: 船期：06月25日
A13: 区域 | C13: 重量 | D13: 12-70 | E13: 71-99 | F13: 100+ | G13: 签收时效（自然日） | H13: 预计提取时间 | K13: 截单时间 | L13: 最晚进仓时间 | M13: 开船时间 | N13: 备注
A14: 美东 (邮编0.1.2.3开头) | C14: 价格 | D14: =F14+6 -> 21 | E14: =F14+3 -> 18 | F14: 15 | G14: 18-19天 | H14: 开船后16-18天提取(如遇节假日、海关查验、码头停摆、罢工等不可抗拒因素除外） | K14: 周五 | L14: 周日 | M14: 周四 | N14: 1,比重1：200 价格本减0.5/KG 1:300价格本减1/KG （比重只适用于100KG以上的货物） 2,单件最低计费重量12KG,单件不足12KGS按12KGS计费，抛货体积除以6000. 3，单独报关200/票，买单免收报关费 4，系统下单渠道：美森限时达
A15: 美中 (邮编4.5.6.7开头) | C15: 价格 | D15: =F15+6 -> 20 | E15: =F15+3 -> 17 | F15: 14 | G15: 16-17天
A16: 美西(邮编8.9开头) | C16: 价格 | D16: =F16+6 -> 18.5 | E16: =F16+3 -> 15.5 | F16: 12.5 | G16: 14-15天
A17: 限时达统配 (LOS ANGELES拆柜）（合德快提） | N17: 船期：06月25日
A18: 区域 | C18: 重量 | D18: 12-70 | E18: 71-99 | F18: 100+ | G18: 签收时效（自然日） | H18: 预计提取时间 | K18: 截单时间 | L18: 最晚进仓时间 | M18: 开船时间 | N18: 备注
A19: 美东 (邮编0.1.2.3开头) | C19: 价格 | D19: =F19+6 -> 19 | E19: =F19+3 -> 16 | F19: 13 | G19: 19-20天 | H19: 开船后18天提取-晚一天赔1元/KG，最高赔付3元/KG.(如遇节假日、海关查验、码头停摆、罢工等不可抗拒因素除外） | K19: 周五 | L19: 周日 | M19: 周四 | N19: 1,比重1：200 价格本减0.5/KG 1:300价格本减1/KG （比重只适用于100KG以上的货物） 2,单件最低计费重量12KG,单件不足12KGS按12KGS计费，抛货体积除以6000. 3，单独报关200/票，买单免收报关费 4，系统下单渠道：限时达统配
A20: 美中 (邮编4.5.6.7开头) | C20: 价格 | D20: =F20+6 -> 18 | E20: =F20+3 -> 15 | F20: 12 | G20: 17-18天
A21: 美西(邮编8.9开头) | C21: 价格 | D21: =F21+6 -> 16.5 | E21: =F21+3 -> 13.5 | F21: 10.5 | G21: 15-16天
A22: 美西OA/ZIM普船 (LOS ANGELES拆柜） | N22: 船期：06月27日
A23: 区域 | C23: 重量 | D23: 12-70 | E23: 71-99 | F23: 100+ | G23: 签收时效（自然日） | H23: 预计提取时间 | K23: 截单时间 | L23: 最晚进仓时间 | M23: 开船时间 | N23: 备注
A24: 美东 (邮编0.1.2.3开头) | C24: 价格 | D24: =F24+6 -> 18 | E24: =F24+3 -> 15 | F24: 12 | G24: 25-26天 | H24: 开船后18-22天提取(如遇节假日、海关查验、码头停摆、罢工等不可抗拒因素除外） | K24: 周五 | L24: 周日 | M24: 周六 | N24: 1,比重1：200 价格本减0.5/KG 1:300价格本减1/KG （比重只适用于100KG以上的货物） 2,单件最低计费重量12KG,单件不足12KGS按12KGS计费，抛货体积除以6000. 3，单独报关200/票，买单免收报关费 4，系统下单渠道：美西OA普船
A25: 美中 (邮编4.5.6.7开头) | C25: 价格 | D25: =F25+6 -> 17 | E25: =F25+3 -> 14 | F25: 11 | G25: 23-24天
A26: 美西(邮编8.9开头) | C26: 价格 | D26: =F26+6 -> 15.5 | E26: =F26+3 -> 12.5 | F26: 9.5 | G26: 20-22天
A27: 美东普船 (纽约拆柜） | N27: 船期：06月26日
A28: 区域 | C28: 重量 | D28: 12-70 | E28: 71-99 | F28: 100+ | G28: 签收时效（自然日） | H28: 预计提取时间 | K28: 截单时间 | L28: 最晚进仓时间 | M28: 开船时间 | N28: 备注
A29: 美东 (邮编0,1开头) | C29: 价格 | D29: =F29+6 -> 16.5 | E29: =F29+3 -> 13.5 | F29: 10.5 | G29: 32-35天 | H29: 开船后35-40天提取(如遇节假日、海关查验、码头停摆、罢工等不可抗拒因素除外） | K29: 周五 | L29: 周日 | M29: 周五 | N29: 1,比重1：200 价格本减0.5/KG 1:300价格本减1/KG （比重只适用于100KG以上的货物） 2,单件最低计费重量12KG,单件不足12KGS按12KGS计费，抛货体积除以6000. 3，单独报关200/票，买单免收报关费 4，系统下单渠道：美东普船
A30: 注意:以上派送价格为亚马逊仓库地址，非FBA商业地址不加钱，带电带磁不加钱，产品附加费及派送附加费见附加项目说明。
A31: 上海仓库：上海市松江区泗泾镇九干路220号12栋105 义乌仓库：义乌市深国际物流港A6-2-1(二层） 宁波仓库：浙江省宁波市北仑区霞浦街道山下周228号 深圳仓库：深圳市龙岗区丹平北路金鹏物流园B区6栋1-3号 青岛仓库：青岛淮河西路169号山东高速物流园D区19-20号
A32: 美森至尊达，美森限时达，限时达统配，美东普船 货交深圳/青岛，加收0.7/KG 美西OA普船，货交深圳/青岛不加钱
B33: 产品附加费说明 | L33: 加收金额 | N33: 备注
A34: 1 | B34: 木制品/竹制品/等动植物制品，若不是报关件，需要加收额外附加费 (若是报关件不收此附加费，客户自行做商检，我司代办商检费实报实销） | L34: RMB1/KG MAX:RMB500
A35: 2 | B35: 钢/铝/铜制品及其衍生品（232-I-A） | L35: RMB1/KG
A36: 3 | B36: 鞋子/包/圆珠笔/服装/U盘/内存卡类产品 | L36: RMB1/KG
A37: 4 | B37: 反倾销品 | L37: 单独确认
A38: 5 | B38: 快递派送 NEW YORK市区 | L38: RMB5/KG | N38: 此类费用重复叠加
A39: 6 | B39: 快递派送的指定FEDEX GROUND或者UPS GROUND | L39: RMB1/KG
A40: 7 | B40: 住宅地址 | L40: RMB25/件
A41: 8 | B41: 偏远地区附加费 | L41: RMB30/件
A42: 9 | B42: 特别偏远地区附加费 | L42: RMB120/件
A43: 10 | B43: 更改地址费（包括更改，拦截，退回发件地址） | L43: RMB120/件 | N43: 货交UPS或者FEDEX后，更改有可能造成包裹丢失； 此操作导致包裹丢失我司不负责赔偿。
A44: 11 | B44: 任何包装在金属或木制的托运容器之物件。 | L44: RMB120/件 | N44: 此类费用重复叠加
A45: 12 | B45: 任何未有以瓦楞纸完整包裹好的圆柱形物件，如圆桶、鼓、提桶或轮胎等。 | L45: RMB120/件
A46: 13 | B46: 任何最长一边之长度超过120厘米或第二最长边的长度超过75厘米的包裹。 | L46: RMB120/件
...

Sheet FBA仓库特价仓
A2: 亚马逊仓库特价
F3: 币种：人民币
A4: 仓库代码 | C4: 100KG+（1:6000） | F4: 1CBM起收（400KG=1CBM) | I4: 渠道名称 | J4: 签收时效(自然日） | K4: 备注
A5: ONT8/LGB8/SBD1/LAX9/POC1/POC3 | C5: 5.5 | F5: 1060 | I5: 美西OA普船 | J5: 27-30天 | K5: 仓点不同，不能合并报关; 单个纸箱毛重小22KG; 纸箱最长边小于63.5CM;
A6: POC2/XLX7/LGB6/ LGB4/SNA4/IUSJ/IUSP/IUSQ/IUSW/IUTI/SBD2 | C6: 5.6 | F6: 1079 | I6: 美西OA普船 | J6: 27-30天
A7: LAS1/VGT2/FAT2/QXY8/LAS6/PSP3 | C7: 5.8 | F7: 1117 | I7: 美西OA普船 | J7: 27-35天
A8: GEU2/GEU5/MIT2/MCE1/GEU3 | C8: 6 | F8: 1155 | I8: 美西OA普船 | J8: 27-35天
A9: IUTE/SCK4/GYR2/GYR3/SMF3/TCY1/SCK8 /TCY2/HLI2/SCK1/OAK3/PHX5/PHX7/SMF6/MCC1 | C9: 6.2 | F9: 1194 | I9: 美西OA普船 | J9: 30-45天
A10: FTW1/ABQ2/IUSF/SLC2/SLC3 | C10: 7.4 | F10: 1422 | I10: 美西OA/达拉斯/休斯顿普船 | J10: 30-45天
A11: FTW5/SAT4/IAH3/DFW6/SAT1/PSC2 /OKC2/DEN8/GEG2/AMA1 | C11: 8.1 | F11: 1555 | I11: 美西OA/达拉斯/休斯顿普船 | J11: 35-55天
A12: MDW2/IND9/FWA4/IGQ2/ORD2/STL3/STL4/RFD2 /MQJ1/LFT1/LAN2/PPO4/BNA6/CMH2/FOE1 | C12: 8.3 | F12: 1593 | I12: 美西OA/芝加哥普船 | J12: 35-55天
A15: 以上报价适用于货交上海/义乌仓/深圳/青岛/宁波,其它城市费用另行确认。
B16: 产品附加费说明 | J16: 加收金额 | K16: 备注
A17: 1 | B17: 木制品/竹制品/等动植物制品，若不是报关件，需要加收额外附加费 (若是报关件不收此附加费，客户自行做商检，我司代办商检费实报实销） | J17: RMB1/KG MAX:RMB500
A18: 2 | B18: 钢/铝/铜制品及其衍生品（232-I-A） | J18: RMB1/KG
A19: 3 | B19: 鞋子/包/圆珠笔/服装/U盘/内存卡类产品 | J19: RMB1/KG
A20: 4 | B20: 反倾销品 | J20: 不接
A21: 操作说明
A22: 1 | B22: FBA货物每件货物需贴2个以上合格的FBA标签,在货物的外包装和单件货物上必须要有MADE IN CHINA。
A23: 2 | B23: 不接受易变形或太软的纸箱，如亚马逊仓库或其他收货仓库因包装问题或其他问题产生拒收等原因，破损丢件，我司不承担任何责任。
A24: 3 | B24: 目的地海关认定货物是品牌货物，或者是CE、蓝牙、HDMI、FDA、FCC、Lacey Act、DOT等认证的问题，或者货物属于当地反倾销,或不符合目的地国家进口要求的货物，客人需要提供相应授权书或认证报告，如果提供不了导致货物扣关甚至退运而产生的所有责任和相关费用将由发件人承担。
A25: 4 | B25: 此渠道不接仿牌、贵金属、侵权产品、危险品、成人用品、敏感品、儿童玩具类、违禁品、易燃易爆等明确规定的，特殊产品请单询。 如果瞒报发现冲货，永久终止合作不做解释，并承担由此产生的海关扣关罚款及连带责任！
A26: 5 | B26: 所有客户暂扣件及改派地址业务，我司不承诺百分百成功，如有此问题我司不承担任何赔偿。
A27: 6 | B27: 卡车赔偿标准： 1.理赔需要提供采购发票等相关资料，以便对货值的合理性进行评估； 2.在国际海运运输过程中如货物丢失，按RMB20/KG赔偿，退运费，最高不能超过货值； 3.卡车提取之后整托丢失的，按照USD500/托理赔，最高不能超过货值； 4.卡派货物请客户自己购买保险，否则只能按照我司赔偿标准。 特别申明以下情况不受理赔偿： 1）如因侵权/瞒报问题海关扣货，我司不承担任何责任并且保留追究发件人因此带来对我司的损失的赔偿； 2）如货物没有按照实际货物申报、当地禁止进口等原因而导致的海关扣货，此情况不在赔偿范围之内，我司只是协助发件人提供清关文件； 3）如因客户货物本身质量问题以及涉及到具体的认证问题等导致海关扣货，均不受理赔偿； 4）如遇战争，自然灾害等不可抗力因素导致货物破坏或灭失，不受理赔偿； 5）在运输过程中如遇到航班和船公司延误/清关延误等引起的总体时效延误，均不受理赔偿； 6）快递派运输途中因外包装破损导致产品缺失，我司可以协助调查，不在我司理赔范围内； 7）易碎品不接受任何损坏赔偿。 8）卡派过程中如果单箱丢失、少件、货损，我司可以协助调查，最终以卡车公司受理结果为准，不在我司赔偿范围内； 9）卡车POD上面没有签收产品破损具体件数/丢失具体件数/现场照片，我司不受理赔偿； 索赔期限及规则： 卡派索赔程序： a. 客户要在签收后7个工作日内告知我司，超过30个工作日未提供完整资料的，我司将不再接受理赔申请； b. 客户在索赔期间需要积极协助我司进行索赔，提供完整资料之后3个月，我司正常理赔给客人； 注：若逾期未提供完整相应索赔资料，则相应责任由客户自行承担，我司不再接受理赔申请。
A29: 特别提示：如客户一旦同意接受我司服务，我司将默认为客户已详细阅读过此价格表备注内容，并接受各条款的约束!

Sheet 美西OA普船美转墨卡派
A2: 美西OA普船美转墨卡派
A3: =美国海派包税!N22 -> 船期：06月27日 | D3: 币种：人民币
A4: 转运仓库 | B4: 200KG=1CBM | E4: 签收时效
A5: 墨西哥城中心30MILES以内, LTL送商业/FBA地址 | B5: 4CBM+ | C5: RMB3340/CBM | E5: 35-50天左右
B6: 10CBM+ | C6: RMB2959/CBM | E6: 35-50天左右
A7: FTL直送价格单独确认
A10: 以上报价适用于货交上海义乌仓，交深圳/青岛需要加收0.7/KG,其它城市费用另行确认。
B11: 产品附加费说明
A12: 1 | B12: 木制品/竹制品/等动植物制品，若不是报关件，需要加收额外附加费 (若是报关件不收此附加费，客户自行做商检，我司代办商检费实报实销） | E12: RMB500/票
A13: 2 | B13: 纺织品/高税率产品 | E13: USD50/CBM
A14: 3 | B14: 高货值货物/敏感货物：电池、电子元件、无人机等 | E14: 价格单独确认
A15: 操作说明
A16: 1 | B16: FBA货物每件货物需贴2个以上合格的FBA标签,在货物的外包装和单件货物上必须要有MADE IN CHINA。
A17: 2 | B17: 不接受易变形或太软的纸箱，如亚马逊仓库或其他收货仓库因包装问题或其他问题产生拒收等原因，破损丢件，我司不承担任何责任。
A18: 3 | B18: 目的地海关认定货物是品牌货物，或者是CE、蓝牙、HDMI、FDA、FCC、Lacey Act、DOT等认证的问题，或者货物属于当地反倾销,或不符合目的地国家进口要求的货物，客人需要提供相应授权书或认证报告，如果提供不了导致货物扣关甚至退运而产生的所有责任和相关费用将由发件人承担。
A19: 4 | B19: 此渠道不接食品、仿牌、贵金属、侵权产品、危险品、成人用品、敏感品、儿童玩具类、违禁品、易燃易爆等明确规定的，特殊产品请单询。 如果瞒报发现冲货，永久终止合作不做解释，并承担由此产生的海关扣关罚款及连带责任！
A20: 5 | B20: 所有客户暂扣件及改派地址业务，我司不承诺百分百成功，如有此问题我司不承担任何赔偿。
A21: 6 | B21: 卡车赔偿标准： 1.理赔需要提供采购发票等相关资料，以便对货值的合理性进行评估； 2.运输过程中货物丢失/被抢，免运费且承诺赔付1倍运费，最高不能超过货值； 3.高货值货物请客户自己购买保险，否则只能按照我司赔偿标准。 特别申明以下情况不受理赔偿： 1）如因侵权/瞒报问题海关扣货，我司不承担任何责任并且保留追究发件人因此带来对我司的损失的赔偿； 2）如货物没有按照实际货物申报、当地禁止进口等原因而导致的海关扣货，此情况不在赔偿范围之内，我司只是协助发件人提供清关文件； 3）如因客户货物本身质量问题以及涉及到具体的认证问题等导致海关扣货，均不受理赔偿； 4）如遇战争，自然灾害等不可抗力因素导致货物破坏或灭失，不受理赔偿； 5）在运输过程中如遇到航班和船公司延误/清关延误等引起的总体时效延误，均不受理赔偿； 6）易碎品不接受任何损坏赔偿。 7）卡派过程中如果单箱丢失、少件、货损，我司可以协助调查，最终以卡车公司受理结果为准，不在我司赔偿范围内； 8）卡车POD上面没有签收产品破损具体件数/丢失具体件数/现场照片，我司不受理赔偿； 索赔期限及规则： 卡派索赔程序： a. 客户要在签收后7个工作日内告知我司，超过30个工作日未提供完整资料的，我司将不再接受理赔申请； b. 客户在索赔期间需要积极协助我司进行索赔，提供完整资料之后3个月，我司正常理赔给客人； 注：若逾期未提供完整相应索赔资料，则相应责任由客户自行承担，我司不再接受理赔申请。
A22: 特别提示：如客户一旦同意接受我司服务，我司将默认为客户已详细阅读过此价格表备注内容，并接受各条款的约束!

Sheet 限时达统配美转加FBA卡车
A2: 限时达统配美转加FBA卡派
A3: =美国海派包税!N17 -> 船期：06月25日 | E3: 币种：人民币
A4: 转运仓库 | B4: FBA仓库代码 | C4: 100KG+（1:6000） | F4: 签收时效（自然日）
A5: TOR仓库 1:200单价优惠0.5/KG 1:300单价优惠1/KG | B5: YYZ | C5: 12.953593 | F5: 20-25天
B6: YOO1 | C6: 13.158683 | F6: 20-25天
B7: YHM1 | C7: 13.158683 | F7: 20-25天
B8: YXU1 | C8: 13.363772 | F8: 20-25天
B9: YGK1 | C9: 13.773952 | F9: 20-25天
B10: YOW | C10: 13.979042 | F10: 20-25天
A11: CAL仓库 1:200单价优惠0.5/KG 1:300单价优惠1/KG | B11: YYC | C11: 13.056138 | F11: 22-27天
B12: YEG | C12: 13.671407 | F12: 22-27天
B13: YVR | C13: 15.107036 | F13: 22-27天
A16: 以上报价适用于货交上海义乌仓，交深圳/青岛需要加收0.7/KG,其它城市费用另行确认。
B17: 产品附加费说明
A18: 1 | B18: 木制品/竹制品/等动植物制品，若不是报关件，需要加收额外附加费 (若是报关件不收此附加费，客户自行做商检，我司代办商检费实报实销） | F18: RMB1/KG MAX:RMB500
A19: 2 | B19: 鞋子/包/圆珠笔/服装/U盘/内存卡类产品 | F19: RMB1/KG
A20: 3 | B20: 反倾销品 | F20: 不接
A21: 操作说明
A22: 1 | B22: FBA货物每件货物需贴2个以上合格的FBA标签,在货物的外包装和单件货物上必须要有MADE IN CHINA。
A23: 2 | B23: YYZ3收货限制：长度不得超过59inch（149cm），单件重量不超50lbs（22kg）。
A24: 3 | B24: YYZ4收货限制：产品SKU尺寸需要控制在18 inch（45.72cm）*14inch（35.56cm）*10inch（25.4cm）以内，重量要求单件不超过 20 LBS。
A25: 4 | B25: YYZ7收货限制：外箱单边尺寸63CM； 产品SKU尺寸需要控制在18 inch（45.72cm）*14inch（35.56cm）*10inch（25.4cm）以内，重量要求单件不超过 20 LBS。
A26: 5 | B26: YYZ9收货限制：长度59inch（149cm）以内 ，单件重量不超过50lbs（22KG）
A27: 6 | B27: YXU1收货限制：单个纸箱单边尺寸不超25inch（63cm），重量不超50LB（22kg）
A28: 7 | B28: 不接受易变形或太软的纸箱，如亚马逊仓库或其他收货仓库因包装问题或其他问题产生拒收等原因，破损丢件，我司不承担任何责任。
A29: 8 | B29: 目的地海关认定货物是品牌货物，或者是CE、蓝牙、HDMI、FDA、FCC、Lacey Act、DOT等认证的问题，或者货物属于当地反倾销,或不符合目的地国家进口要求的货物，客人需要提供相应授权书或认证报告，如果提供不了导致货物扣关甚至退运而产生的所有责任和相关费用将由发件人承担。
A30: 9 | B30: 此渠道不接食品、仿牌、贵金属、侵权产品、危险品、成人用品、敏感品、儿童玩具类、违禁品、易燃易爆等明确规定的，特殊产品请单询。 如果瞒报发现冲货，永久终止合作不做解释，并承担由此产生的海关扣关罚款及连带责任！
A31: 10 | B31: 所有客户暂扣件及改派地址业务，我司不承诺百分百成功，如有此问题我司不承担任何赔偿。
A32: 11 | B32: 卡车赔偿标准： 1.理赔需要提供采购发票等相关资料，以便对货值的合理性进行评估； 2.在国际海运运输过程中货物丢失，按RMB20/KG赔偿，退运费，最高不能超过货值； 3.卡车提取之后整托丢失的，按照USD500/托理赔，最高不能超过货值，以卡车公司为准，不退运费； 4.卡派货物请客户自己购买保险，否则只能按照我司赔偿标准。 特别申明以下情况不受理赔偿： 1）如因侵权/瞒报问题海关扣货，我司不承担任何责任并且保留追究发件人因此带来对我司的损失的赔偿； 2）如货物没有按照实际货物申报、当地禁止进口等原因而导致的海关扣货，此情况不在赔偿范围之内，我司只是协助发件人提供清关文件； 3）如因客户货物本身质量问题以及涉及到具体的认证问题等导致海关扣货，均不受理赔偿； 4）如遇战争，自然灾害等不可抗力因素导致货物破坏或灭失，不受理赔偿； 5）在运输过程中如遇到航班和船公司延误/清关延误等引起的总体时效延误，均不受理赔偿； 6）快递派运输途中因外包装破损导致产品缺失，我司可以协助调查，不在我司理赔范围内； 7）易碎品不接受任何损坏赔偿。 8）卡派过程中如果单箱丢失、少件、货损，我司可以协助调查，最终以卡车公司受理结果为准，不在我司赔偿范围内； 9）卡车POD上面没有签收产品破损具体件数/丢失具体件数/现场照片，我司不受理赔偿； 索赔期限及规则： 卡派索赔程序： a. 客户要在签收后7个工作日内告知我司，超过30个工作日未提供完整资料的，我司将不再接受理赔申请； b. 客户在索赔期间需要积极协助我司进行索赔，提供完整资料之后3个月，我司正常理赔给客人； 注：若逾期未提供完整相应索赔资料，则相应责任由客户自行承担，我司不再接受理赔申请。
A34: 特别提示：如客户一旦同意接受我司服务，我司将默认为客户已详细阅读过此价格表备注内容，并接受各条款的约束!

Sheet 限时达统配美转加非FBA卡派
A2: 限时达统配美转加卡车
A3: =美国海派包税!N17 -> 船期：06月25日 | E3: 币种：人民币
A4: 转运仓库 | B4: 区域 | C4: 300KG+（1:6000） | D4: 签收时效（自然日） | F4: 备注 | G4: 分区表格查询
A5: TOR仓库始发 | B5: Zone1 | C5: 13.363772 | D5: 21-24天 | F5: 1:200单价优惠0.5/KG 1:300单价优惠1/KG （对应分区，请查看分区表） | G5: 加拿大TOR商卡分区表
B6: Zone2 | C6: 13.60988 | D6: 21-24天
B7: Zone3 | C7: 14.286677 | D7: 21-24天
B8: Zone4 | C8: 14.799401 | D8: 21-24天
B9: Zone5 | C9: 15.107036 | D9: 21-24天
B10: Zone6 | C10: 15.312126 | D10: 21-24天
B11: Zone7 | C11: 15.82485 | D11: 21-24天
B12: Zone8 | C12: 16.02994 | D12: 22-25天
B13: Zone9 | C13: 17.260479 | D13: 22-25天
B14: Zone10 | C14: 17.773204 | D14: 22-25天
B15: Zone11 | C15: 19.516467 | D15: 22-25天
B16: Zone12 | C16: 20.234281 | D16: 22-25天
B17: Zone13 | C17: 21.362275 | D17: 22-25天
... B19: Zone15 | C19: 23.310629 | D19: 22-25天
A20: CAL仓库始发 | B20: Zone1 | C20: 13.302246 | D20: 21-24天 | G20: 加拿大CAL商卡分区表
B21: Zone2 | C21: 14.122605 | D21: 21-24天
B22: Zone3 | C22: 15.312126 | D22: 21-24天
B23: Zone4 | C23: 16.23503 | D23: 21-24天
B24: Zone5 | C24: 16.296557 | D24: 21-24天
B25: Zone6 | C25: 16.337575 | D25: 21-24天
B26: Zone7 | C26: 16.481138 | D26: 21-24天
B27: Zone8 | C27: 18.183383 | D27: 22-25天
B28: Zone9 | C28: 19.003743 | D28: 22-25天
B29: Zone10 | C29: 19.516467 | D29: 22-25天
B30: Zone11 | C30: 20.234281 | D30: 22-25天
B31: Zone12 | C31: 21.772455 | D31: 22-25天
B32: Zone13 | C32: 24.336078 | D32: 22-25天
B33: Zone14 | C33: 24.848802 | D33: 22-25天
A36: 以上报价适用于货交上海义乌仓，交深圳/青岛需要加收0.7/KG,其它城市费用另行确认。
B37: 产品附加费说明
A38: 1 | B38: 木制品/竹制品/等动植物制品，若不是报关件，需要加收额外附加费 (若是报关件不收此附加费，客户自行做商检，我司代办商检费实报实销） | F38: RMB1/KG MAX:RMB500
A39: 2 | B39: 鞋子/包/圆珠笔/服装/U盘/内存卡类产品 | F39: RMB1/KG
A40: 3 | B40: 反倾销品 | F40: 不接
A41: 4 | B41: 尾板费用--如收货方没有卸货平台（loading dock）且需要司机卸货至地面上（包含使用手叉车）。 (尾板承重500KG/板，>500KG/板以及货物超长，需要收货人自己安排卸货)。 | F41: 单独确认
A42: 5 | B42: 候时免费半小时，超过时间，USD25/半小时。（不满半小时将按照半小时计算）
A43: 6 | B43: 仓储费用：如因收货人原因，无法收货/联系不上，导致货物暂存在海外仓，将收取USD10/板/周（按照实际占用板位面积收费）。
A44: 操作说明
...

Sheet 限时达统配卡车
A2: 限时达统配卡派（全美非FBA卡派单询）
A3: =美国海派包税!N17 -> 船期：06月25日 | E3: 币种：人民币
A4: 仓库代码 | C4: 100KG+（1:6000） | F4: 1CBM起收（400KG=1CBM) | I4: 签收时效（自然日）
A5: LGB8/ONT8/LAX9/SBD1 | C5: 7.4288922 | F5: 1240.625 | I5: 21-24天
A6: LAX1/LAX2T | C6: 7.5314371 | F6: 1257.75 | I6: 21-24天
A7: LGB4/6/SNA4/POC1/POC2/POC3/SBD2/IUSP/XLX7 | C7: 7.7365269 | F7: 1292 | I7: 21-24天
A8: LAS1/VGT2/GYR2/3/GEU2/3/5/FAT2/SMF3/SCK4/MIT2 | C8: 8.2492515 | F8: 1377.625 | I8: 23-26天
A9: PHX5/MCE1/TCY1/TCY2 | C9: 8.3517964 | F9: 1394.75 | I9: 23-26天
A12: 以上报价适用于货交上海义乌仓，交深圳/青岛需要加收0.7/KG,其它城市费用另行确认。
B13: 产品附加费说明 | G13: 加收金额 | H13: 备注
A14: 1 | B14: 木制品/竹制品/等动植物制品，若不是报关件，需要加收额外附加费 (若是报关件不收此附加费，客户自行做商检，我司代办商检费实报实销） | G14: RMB1/KG MAX:RMB500
A15: 2 | B15: 钢/铝/铜制品及其衍生品（232-I-A） | G15: RMB1/KG
A16: 3 | B16: 鞋子/包/圆珠笔/服装/U盘/内存卡类产品 | G16: RMB1/KG
A17: 4 | B17: 反倾销品 | G17: 单独确认
A18: 操作说明
A19: 1 | B19: FBA货物每件货物需贴2个以上合格的FBA标签,在货物的外包装和单件货物上必须要有MADE IN CHINA。
A20: 2 | B20: 不接受易变形或太软的纸箱，如亚马逊仓库或其他收货仓库因包装问题或其他问题产生拒收等原因，破损丢件，我司不承担任何责任。
A21: 3 | B21: 目的地海关认定货物是品牌货物，或者是CE、蓝牙、HDMI、FDA、FCC、Lacey Act、DOT等认证的问题，或者货物属于当地反倾销,或不符合目的地国家进口要求的货物，客人需要提供相应授权书或认证报告，如果提供不了导致货物扣关甚至退运而产生的所有责任和相关费用将由发件人承担。
A22: 4 | B22: 此渠道不接食品、仿牌、贵金属、侵权产品、危险品、成人用品、敏感品、儿童玩具类、违禁品、易燃易爆等明确规定的，特殊产品请单询。 如果瞒报发现冲货，永久终止合作不做解释，并承担由此产生的海关扣关罚款及连带责任！
A23: 5 | B23: 所有客户暂扣件及改派地址业务，我司不承诺百分百成功，如有此问题我司不承担任何赔偿。
A24: 6 | B24: 卡车赔偿标准： 1.理赔需要提供采购发票等相关资料，以便对货值的合理性进行评估； 2.在国际海运运输过程中货物丢失，按RMB20/KG赔偿，退运费，最高不能超过货值； 3.卡车提取之后整托丢失的，按照USD500/托理赔，最高不能超过货值，以卡车公司为准，不退运费； 4.卡派货物请客户自己购买保险，否则只能按照我司赔偿标准。 特别申明以下情况不受理赔偿： 1）如因侵权/瞒报问题海关扣货，我司不承担任何责任并且保留追究发件人因此带来对我司的损失的赔偿； 2）如货物没有按照实际货物申报、当地禁止进口等原因而导致的海关扣货，此情况不在赔偿范围之内，我司只是协助发件人提供清关文件； 3）如因客户货物本身质量问题以及涉及到具体的认证问题等导致海关扣货，均不受理赔偿； 4）如遇战争，自然灾害等不可抗力因素导致货物破坏或灭失，不受理赔偿； 5）在运输过程中如遇到航班和船公司延误/清关延误等引起的总体时效延误，均不受理赔偿； 6）快递派运输途中因外包装破损导致产品缺失，我司可以协助调查，不在我司理赔范围内； 7）易碎品不接受任何损坏赔偿。 8）卡派过程中如果单箱丢失、少件、货损，我司可以协助调查，最终以卡车公司受理结果为准，不在我司赔偿范围内； 9）卡车POD上面没有签收产品破损具体件数/丢失具体件数/现场照片，我司不受理赔偿； 索赔期限及规则： 卡派索赔程序： a. 客户要在签收后7个工作日内告知我司，超过30个工作日未提供完整资料的，我司将不再接受理赔申请； b. 客户在索赔期间需要积极协助我司进行索赔，提供完整资料之后3个月，我司正常理赔给客人； 注：若逾期未提供完整相应索赔资料，则相应责任由客户自行承担，我司不再接受理赔申请。
A26: 特别提示：如客户一旦同意接受我司服务，我司将默认为客户已详细阅读过此价格表备注内容，并接受各条款的约束!

Sheet 美东NY普船卡车
A2: 美东NY普船海卡 （全美非FBA卡派单询）
A3: =美国海派包税!N27 -> 船期：06月26日
A4: 仓库代码 | C4: 100KG+（1:6000） | D4: 1CBM起收（400KG=1CBM) | E4: 签收时效（自然日）
A5: ABE8/ACY2/TEB6/TEB9/EWR4/EWR9 /XEW5/TTN2/TEB3/TEB4/XEW5 | C5: 6.1 | D5: 1213 | E5: 35-55天
A6: ABE3/ABE4/AVP1/HEA2/AVP3/AVP9/WBW2 | C6: 6.3 | D6: 1251 | E6: 35-55天
A7: HIA1/PHL4/PHL5/PHL6/PIT1/MDT1/MDT4/PIT2/LBE1 | C7: 6.5 | D7: 1289 | E7: 35-55天
A8: IUSL/MDT2/ILG1/KRB2/DCA6/BWI1/HGR2/XLX1/HGR6 | C8: 6.7 | D8: 1327 | E8: 40-55天
A9: ALB1/SWF1/SWF2 | C9: 6.5 | D9: 1289 | E9: 40-55天
A10: BDL6/BOS7/BWI4/CHO1/RIC1/RIC3/XRI3 | C10: 6.9 | D10: 1365 | E10: 40-55天
A13: 以上报价适用于货交上海义乌仓，交深圳/青岛需要加收0.7/KG,其它城市费用另行确认。
B14: 产品附加费说明 | D14: 加收金额
A15: 1 | B15: 木制品/竹制品/等动植物制品，若不是报关件，需要加收额外附加费 (若是报关件不收此附加费，客户自行做商检，我司代办商检费实报实销） | D15: RMB1/KG MAX:RMB500
A16: 2 | B16: 钢/铝/铜制品及其衍生品（232-I-A） | D16: RMB1/KG
A17: 3 | B17: 鞋子/包/圆珠笔/服装/U盘/内存卡类产品 | D17: RMB1/KG
A18: 4 | B18: 反倾销品 | D18: 单独确认
A19: 操作说明
A20: 1 | B20: FBA货物每件货物需贴2个以上合格的FBA标签,在货物的外包装和单件货物上必须要有MADE IN CHINA。
A21: 2 | B21: 不接受易变形或太软的纸箱，如亚马逊仓库或其他收货仓库因包装问题或其他问题产生拒收等原因，破损丢件，我司不承担任何责任。
A22: 3 | B22: 目的地海关认定货物是品牌货物，或者是CE、蓝牙、HDMI、FDA、FCC、Lacey Act、DOT等认证的问题，或者货物属于当地反倾销,货物或不符合目的地国家进口要求的货物，客人需要提供相应授权书或认证报告，如果提供不了导致货物扣关甚至退运而产生的所有责任和相关费用将由发件人承担。
A23: 4 | B23: 此渠道不接食品、仿牌、贵金属、侵权产品、危险品、成人用品、敏感品、儿童玩具类、违禁品、易燃易爆等明确规定的，特殊产品请单询。 如果瞒报发现冲货，永久终止合作不做解释，并承担由此产生的海关扣关罚款及连带责任！
A24: 5 | B24: 所有客户暂扣件及改派地址业务，我司不承诺百分百成功，如有此问题我司不承担任何赔偿。
A25: 6 | B25: 卡车赔偿标准： 1.理赔需要提供采购发票等相关资料，以便对货值的合理性进行评估； 2.在国际海运运输过程中如货物丢失，按RMB20/KG赔偿，退运费，最高不能超过货值； 3.卡车提取之后整托丢失的，按照USD500/托理赔，最高不能超过货值； 4.卡派货物请客户自己购买保险，否则只能按照我司赔偿标准。 特别申明以下情况不受理赔偿： 1）如因侵权/瞒报问题海关扣货，我司不承担任何责任并且保留追究发件人因此带来对我司的损失的赔偿； 2）如货物没有按照实际货物申报、当地禁止进口等原因而导致的海关扣货，此情况不在赔偿范围之内，我司只是协助发件人提供清关文件； 3）如因客户货物本身质量问题以及涉及到具体的认证问题等导致海关扣货，均不受理赔偿； 4）如遇战争，自然灾害等不可抗力因素导致货物破坏或灭失，不受理赔偿； 5）在运输过程中如遇到航班和船公司延误/清关延误等引起的总体时效延误，均不受理赔偿； 6）快递派运输途中因外包装破损导致产品缺失，我司可以协助调查，不在我司理赔范围内； 7）易碎品不接受任何损坏赔偿。 8）卡派过程中如果单箱丢失、少件、货损，我司可以协助调查，最终以卡车公司受理结果为准，不在我司赔偿范围内； 9）卡车POD上面没有签收产品破损具体件数/丢失具体件数/现场照片，我司不受理赔偿； 索赔期限及规则： 卡派索赔程序： a. 客户要在签收后7个工作日内告知我司，超过30个工作日未提供完整资料的，我司将不再接受理赔申请； b. 客户在索赔期间需要积极协助我司进行索赔，提供完整资料之后3个月，我司正常理赔给客人； 注：若逾期未提供完整相应索赔资料，则相应责任由客户自行承担，我司不再接受理赔申请。
A27: 特别提示：如客户一旦同意接受我司服务，我司将默认为客户已详细阅读过此价格表备注内容，并接受各条款的约束!

Sheet 美东SAV普船卡车
A2: 美东萨凡纳普船海卡 （全美非FBA卡派单询）
A3: =美国海派包税!N27 -> 船期：06月26日
A4: 仓库代码 | C4: 21KG+（1:6000） | D4: 0.5CBM起收（400KG=1CBM) | E4: 签收时效（自然日）
A5: XLX6/SAV3/CLT2/CLT3/IUSR/ATL1/ATL3 /ATL8/GSP1/RDU4/RYY2/MGE1/MGE3/JAX3 | C5: 6.6 | D5: 1308 | E5: 40-60天
A6: GSO1/MCO2/TPA2/TPA3/TPA6/RDU2/ATL2 | C6: 6.9 | D6: 1365 | E6: 40-60天
A7: CHA2/BNA2/ORF2/RMN3/TMB8/HSV1/HSV2/ PBI2/PBI3 | C7: 7.1 | D7: 1403 | E7: 40-60天
A10: 以上报价适用于货交上海义乌仓，交深圳/青岛需要加收0.7/KG,其它城市费用另行确认。
B11: 产品附加费说明 | D11: 加收金额
A12: 1 | B12: 木制品/竹制品/等动植物制品，若不是报关件，需要加收额外附加费 (若是报关件不收此附加费，客户自行做商检，我司代办商检费实报实销） | D12: RMB1/KG MAX:RMB500
A13: 2 | B13: 钢/铝/铜制品及其衍生品（232-I-A） | D13: RMB1/KG
A14: 3 | B14: 鞋子/包/圆珠笔/服装/U盘/内存卡类产品(电子手表/机械表类不收) | D14: RMB1/KG
A15: 4 | B15: 反倾销品 | D15: 单独确认
A16: 操作说明
A17: 1 | B17: FBA货物每件货物需贴2个以上合格的FBA标签,在货物的外包装和单件货物上必须要有MADE IN CHINA。
A18: 2 | B18: 不接受易变形或太软的纸箱，如亚马逊仓库或其他收货仓库因包装问题或其他问题产生拒收等原因，破损丢件，我司不承担任何责任。
A19: 3 | B19: 目的地海关认定货物是品牌货物，或者是CE、蓝牙、HDMI、FDA、FCC、Lacey Act、DOT等认证的问题，或者货物属于当地反倾销,或不符合目的地国家进口要求的货物，客人需要提供相应授权书或认证报告，如果提供不了导致货物扣关甚至退运而产生的所有责任和相关费用将由发件人承担。
A20: 4 | B20: 此渠道不接食品、仿牌、贵金属、侵权产品、危险品、成人用品、敏感品、儿童玩具类、违禁品、易燃易爆等明确规定的，特殊产品请单询。 如果瞒报发现冲货，永久终止合作不做解释，并承担由此产生的海关扣关罚款及连带责任！
A21: 5 | B21: 所有客户暂扣件及改派地址业务，我司不承诺百分百成功，如有此问题我司不承担任何赔偿。
A22: 6 | B22: 卡车赔偿标准： 1.理赔需要提供采购发票等相关资料，以便对货值的合理性进行评估； 2.在国际海运运输过程中如货物丢失，按RMB20/KG赔偿，退运费，最高不能超过货值； 3.卡车提取之后整托丢失的，按照USD500/托理赔，最高不能超过货值； 4.卡派货物请客户自己购买保险，否则只能按照我司赔偿标准。 特别申明以下情况不受理赔偿： 1）如因侵权/瞒报问题海关扣货，我司不承担任何责任并且保留追究发件人因此带来对我司的损失的赔偿； 2）如货物没有按照实际货物申报、当地禁止进口等原因而导致的海关扣货，此情况不在赔偿范围之内，我司只是协助发件人提供清关文件； 3）如因客户货物本身质量问题以及涉及到具体的认证问题等导致海关扣货，均不受理赔偿； 4）如遇战争，自然灾害等不可抗力因素导致货物破坏或灭失，不受理赔偿； 5）在运输过程中如遇到航班和船公司延误/清关延误等引起的总体时效延误，均不受理赔偿； 6）快递派运输途中因外包装破损导致产品缺失，我司可以协助调查，不在我司理赔范围内； 7）易碎品不接受任何损坏赔偿。 8）卡派过程中如果单箱丢失、少件、货损，我司可以协助调查，最终以卡车公司受理结果为准，不在我司赔偿范围内； 9）卡车POD上面没有签收产品破损具体件数/丢失具体件数/现场照片，我司不受理赔偿； 索赔期限及规则： 卡派索赔程序： a. 客户要在签收后7个工作日内告知我司，超过30个工作日未提供完整资料的，我司将不再接受理赔申请； b. 客户在索赔期间需要积极协助我司进行索赔，提供完整资料之后3个月，我司正常理赔给客人； 注：若逾期未提供完整相应索赔资料，则相应责任由客户自行承担，我司不再接受理赔申请。
A24: 特别提示：如客户一旦同意接受我司服务，我司将默认为客户已详细阅读过此价格表备注内容，并接受各条款的约束!

Sheet 美森至尊达-卡派
A2: 上海至尊达CLX-卡派（全美非FBA卡派单询）
A3: =美国海派包税!N7 -> 船期：06月24日 | E3: 币种：人民币
A4: 仓库代码 | C4: 100KG+（1:6000） | F4: 1CBM起收（400KG=1CBM) | I4: 签收时效（自然日）
A5: LGB8/ONT8/LAX9/SBD1 | C5: 10.416916 | F5: 1739.625 | I5: 16-20天
A6: LAX1/LAX2T | C6: 10.519461 | F6: 1756.75 | I6: 16-20天
A7: LGB4/6/SNA4/POC1/POC2/POC3/SBD2/IUSP/XLX7 | C7: 10.724551 | F7: 1791 | I7: 18-22天
A8: LAS1/VGT2/GYR2/3/GEU2/3/5/FAT2/SMF3/SCK4/MIT2 | C8: 11.237275 | F8: 1876.625 | I8: 18-22天
A9: PHX5/MCE1/TCY1/TCY2 | C9: 11.33982 | F9: 1893.75 | I9: 18-22天
A12: 以上报价适用于货交上海义乌仓，交深圳/青岛需要加收0.7/KG,其它城市费用另行确认。
B13: 产品附加费说明 | G13: 加收金额 | H13: 备注
A14: 1 | B14: 木制品/竹制品/等动植物制品，若不是报关件，需要加收额外附加费 (若是报关件不收此附加费，客户自行做商检，我司代办商检费实报实销） | G14: RMB1/KG MAX:RMB500
A15: 2 | B15: 钢/铝/铜制品及其衍生品（232-I-A） | G15: RMB1/KG
A16: 3 | B16: 鞋子/包/圆珠笔/服装/U盘/内存卡类产品 | G16: RMB1/KG
A17: 4 | B17: 反倾销品 | G17: 单独确认
A18: 操作说明
A19: 1 | B19: FBA货物每件货物需贴2个以上合格的FBA标签,在货物的外包装和单件货物上必须要有MADE IN CHINA。
A20: 2 | B20: 不接受易变形或太软的纸箱，如亚马逊仓库或其他收货仓库因包装问题或其他问题产生拒收等原因，破损丢件，我司不承担任何责任。
A21: 3 | B21: 目的地海关认定货物是品牌货物，或者是CE、蓝牙、HDMI、FDA、FCC、Lacey Act、DOT等认证的问题，或者货物属于当地反倾销,或不符合目的地国家进口要求的货物，客人需要提供相应授权书或认证报告，如果提供不了导致货物扣关甚至退运而产生的所有责任和相关费用将由发件人承担。
A22: 4 | B22: 此渠道不接食品、仿牌、贵金属、侵权产品、危险品、成人用品、敏感品、儿童玩具类、违禁品、易燃易爆等明确规定的，特殊产品请单询。 如果瞒报发现冲货，永久终止合作不做解释，并承担由此产生的海关扣关罚款及连带责任！
A23: 5 | B23: 所有客户暂扣件及改派地址业务，我司不承诺百分百成功，如有此问题我司不承担任何赔偿。
A24: 6 | B24: 卡车赔偿标准： 1.理赔需要提供采购发票等相关资料，以便对货值的合理性进行评估； 2.在国际海运运输过程中如货物丢失，按RMB20/KG赔偿，退运费，最高不能超过货值； 3.卡车提取之后整托丢失的，按照USD500/托理赔，最高不能超过货值； 4.卡派货物请客户自己购买保险，否则只能按照我司赔偿标准。 特别申明以下情况不受理赔偿： 1）如因侵权/瞒报问题海关扣货，我司不承担任何责任并且保留追究发件人因此带来对我司的损失的赔偿； 2）如货物没有按照实际货物申报、当地禁止进口等原因而导致的海关扣货，此情况不在赔偿范围之内，我司只是协助发件人提供清关文件； 3）如因客户货物本身质量问题以及涉及到具体的认证问题等导致海关扣货，均不受理赔偿； 4）如遇战争，自然灾害等不可抗力因素导致货物破坏或灭失，不受理赔偿； 5）在运输过程中如遇到航班和船公司延误/清关延误等引起的总体时效延误，均不受理赔偿； 6）快递派运输途中因外包装破损导致产品缺失，我司可以协助调查，不在我司理赔范围内； 7）易碎品不接受任何损坏赔偿。 8）卡派过程中如果单箱丢失、少件、货损，我司可以协助调查，最终以卡车公司受理结果为准，不在我司赔偿范围内； 9）卡车POD上面没有签收产品破损具体件数/丢失具体件数/现场照片，我司不受理赔偿； 索赔期限及规则： 卡派索赔程序： a. 客户要在签收后7个工作日内告知我司，超过30个工作日未提供完整资料的，我司将不再接受理赔申请； b. 客户在索赔期间需要积极协助我司进行索赔，提供完整资料之后3个月，我司正常理赔给客人； 注：若逾期未提供完整相应索赔资料，则相应责任由客户自行承担，我司不再接受理赔申请。
A26: 特别提示：如客户一旦同意接受我司服务，我司将默认为客户已详细阅读过此价格表备注内容，并接受各条款的约束!

Sheet 美森限时达-卡派
A2: 上海美森限时达MAX-卡派（全美非FBA地址卡派单询）
A3: =美国海派包税!N12 -> 船期：06月25日 | E3: 币种：人民币
A4: 仓库代码 | C4: 100KG+（1:6000） | F4: 1CBM起收（400KG=1CBM) | I4: 签收时效（自然日）
A5: LGB8/ONT8/LAX9/SBD1 | C5: 9.6025449 | F5: 1603.625 | I5: 20-22天
A6: LAX1/LAX2T | C6: 9.7050898 | F6: 1620.75 | I6: 20-22天
A7: LGB4/6/SNA4/POC1/POC2/POC3/SBD2/IUSP/XLX7 | C7: 9.9101796 | F7: 1655 | I7: 22-24天
A8: LAS1/VGT2/GYR2/3/GEU2/3/5/FAT2/SMF3/SCK4/MIT2 | C8: 10.422904 | F8: 1740.625 | I8: 22-24天
A9: PHX5/MCE1/TCY1/TCY2 | C9: 10.525449 | F9: 1757.75 | I9: 24-26天
A12: 以上报价适用于货交上海义乌仓，交深圳/青岛需要加收0.7/KG,其它城市费用另行确认。
B13: 产品附加费说明 | G13: 加收金额 | H13: 备注
A14: 1 | B14: 木制品/竹制品/等动植物制品，若不是报关件，需要加收额外附加费 (若是报关件不收此附加费，客户自行做商检，我司代办商检费实报实销） | G14: RMB1/KG MAX:RMB500
A15: 2 | B15: 钢/铝/铜制品及其衍生品（232-I-A） | G15: RMB1/KG
A16: 3 | B16: 鞋子/包/圆珠笔/服装/U盘/内存卡类产品 | G16: RMB1/KG
A17: 4 | B17: 反倾销品 | G17: 单独确认
A18: 操作说明
A19: 1 | B19: FBA货物每件货物需贴2个以上合格的FBA标签,在货物的外包装和单件货物上必须要有MADE IN CHINA。
A20: 2 | B20: 不接受易变形或太软的纸箱，如亚马逊仓库或其他收货仓库因包装问题或其他问题产生拒收等原因，破损丢件，我司不承担任何责任。
A21: 3 | B21: 目的地海关认定货物是品牌货物，或者是CE、蓝牙、HDMI、FDA、FCC、Lacey Act、DOT等认证的问题，或者货物属于当地反倾销,或不符合目的地国家进口要求的货物，客人需要提供相应授权书或认证报告，如果提供不了导致货物扣关甚至退运而产生的所有责任和相关费用将由发件人承担。
A22: 4 | B22: 此渠道不接食品、仿牌、贵金属、侵权产品、危险品、成人用品、敏感品、儿童玩具类、违禁品、易燃易爆等明确规定的，特殊产品请单询。 如果瞒报发现冲货，永久终止合作不做解释，并承担由此产生的海关扣关罚款及连带责任！
A23: 5 | B23: 所有客户暂扣件及改派地址业务，我司不承诺百分百成功，如有此问题我司不承担任何赔偿。
A24: 6 | B24: 卡车赔偿标准： 1.理赔需要提供采购发票等相关资料，以便对货值的合理性进行评估； 2.在国际海运运输过程中如货物丢失，按RMB20/KG赔偿，退运费，最高不能超过货值； 3.卡车提取之后整托丢失的，按照USD500/托理赔，最高不能超过货值； 4.卡派货物请客户自己购买保险，否则只能按照我司赔偿标准。 特别申明以下情况不受理赔偿： 1）如因侵权/瞒报问题海关扣货，我司不承担任何责任并且保留追究发件人因此带来对我司的损失的赔偿； 2）如货物没有按照实际货物申报、当地禁止进口等原因而导致的海关扣货，此情况不在赔偿范围之内，我司只是协助发件人提供清关文件； 3）如因客户货物本身质量问题以及涉及到具体的认证问题等导致海关扣货，均不受理赔偿； 4）如遇战争，自然灾害等不可抗力因素导致货物破坏或灭失，不受理赔偿； 5）在运输过程中如遇到航班和船公司延误/清关延误等引起的总体时效延误，均不受理赔偿； 6）快递派运输途中因外包装破损导致产品缺失，我司可以协助调查，不在我司理赔范围内； 7）易碎品不接受任何损坏赔偿。 8）卡派过程中如果单箱丢失、少件、货损，我司可以协助调查，最终以卡车公司受理结果为准，不在我司赔偿范围内； 9）卡车POD上面没有签收产品破损具体件数/丢失具体件数/现场照片，我司不受理赔偿； 索赔期限及规则： 卡派索赔程序： a. 客户要在签收后7个工作日内告知我司，超过30个工作日未提供完整资料的，我司将不再接受理赔申请； b. 客户在索赔期间需要积极协助我司进行索赔，提供完整资料之后3个月，我司正常理赔给客人； 注：若逾期未提供完整相应索赔资料，则相应责任由客户自行承担，我司不再接受理赔申请。
A26: 特别提示：如客户一旦同意接受我司服务，我司将默认为客户已详细阅读过此价格表备注内容，并接受各条款的约束!

Sheet 美西OA普船卡派
A2: 美西OA/ZIM普船卡派 （全美非FBA卡派单询）
A3: =美国海派包税!N22 -> 船期：06月27日 | F3: 币种：人民币
A4: 仓库代码 | C4: 100KG+（1:6000） | F4: 1CBM起收（400KG=1CBM) | I4: 签收时效（自然日）
A5: ONT8/LGB8/LAX9/SBD1/POC1/POC2/POC3/IUSP/IUSJ SNA4/IUSW/IUTI/IUSQ/LGB6/PSP3 Walmart: LAX1+LAX2T | C5: 5.6 | F5: 1072 | I5: 27-30天
A6: GYR3/GYR2/SMF3/SCK4/LAS1/VGT2/ GEU2/GEU3/GEU5/MIT2/SCK8/TCY2/TCY1/ FAT2/SMF6/MCE1/PHX7/PHX5/IUTE/OAK3 | C6: 6.1 | F6: 1170 | I6: 27-30天
A7: ABQ2 | C7: 7 | F7: 1242 | I7: 28-32天
A8: IAH3/SAT4 | C8: 7.5 | F8: 1337 | I8: 28-32天
A9: PSC2/DEN8/DEN2 | C9: 7.6 | F9: 1356 | I9: 28-32天
A10: DFW6/SAT1/AMA1/IUSF/IUTH/IUSF/ICT2/OKC2 TX+WA+CO+KS商业地址大于15CBM（需有Loading dock） | C10: 7.7 | F10: 1380 | I10: 30-34天
A11: MDW2/IND9/FWA4/MEM1/MQJ1 | C11: 8.1 | F11: 1441 | I11: 30-34天
A12: MKC4/LIT2/FOE1/GEG2/PDX7 IL+IN商业地址大于15CBM（需有Loading dock） | C12: 8.3 | F12: 1480 | I12: 30-34天
A13: STL4/PPO4/LAN2/BNA6/CMH2/CMH3 | C13: 8.6 | F13: 1537 | I13: 30-34天
A16: 以上报价适用于货交上海/义乌仓/深圳/青岛/宁波,其它城市费用另行确认。
B17: 产品附加费说明 | G17: 加收金额 | H17: 备注
A18: 1 | B18: 木制品/竹制品/等动植物制品，若不是报关件，需要加收额外附加费 (若是报关件不收此附加费，客户自行做商检，我司代办商检费实报实销） | G18: RMB1/KG MAX:RMB500
A19: 2 | B19: 钢/铝/铜制品及其衍生品（232-I-A） | G19: RMB1/KG
A20: 3 | B20: 鞋子/包/圆珠笔/服装/U盘/内存卡类产品 | G20: RMB1/KG
A21: 4 | B21: 反倾销品 | G21: 单独确认
A22: 操作说明
A23: 1 | B23: FBA货物每件货物需贴2个以上合格的FBA标签,在货物的外包装和单件货物上必须要有MADE IN CHINA。
A24: 2 | B24: 不接受易变形或太软的纸箱，如亚马逊仓库或其他收货仓库因包装问题或其他问题产生拒收等原因，破损丢件，我司不承担任何责任。
A25: 3 | B25: 目的地海关认定货物是品牌货物，或者是CE、蓝牙、HDMI、FDA、FCC、Lacey Act、DOT等认证的问题，或者货物属于当地反倾销,或不符合目的地国家进口要求的货物，客人需要提供相应授权书或认证报告，如果提供不了导致货物扣关甚至退运而产生的所有责任和相关费用将由发件人承担。
A26: 4 | B26: 此渠道不接仿牌、贵金属、侵权产品、危险品、成人用品、敏感品、儿童玩具类、违禁品、易燃易爆等明确规定的，特殊产品请单询。 如果瞒报发现冲货，永久终止合作不做解释，并承担由此产生的海关扣关罚款及连带责任！
A27: 5 | B27: 所有客户暂扣件及改派地址业务，我司不承诺百分百成功，如有此问题我司不承担任何赔偿。
A28: 6 | B28: 卡车赔偿标准： 1.理赔需要提供采购发票等相关资料，以便对货值的合理性进行评估； 2.在国际海运运输过程中如货物丢失，按RMB20/KG赔偿，退运费，最高不能超过货值； 3.卡车提取之后整托丢失的，按照USD500/托理赔，最高不能超过货值； 4.卡派货物请客户自己购买保险，否则只能按照我司赔偿标准。 特别申明以下情况不受理赔偿： 1）如因侵权/瞒报问题海关扣货，我司不承担任何责任并且保留追究发件人因此带来对我司的损失的赔偿； 2）如货物没有按照实际货物申报、当地禁止进口等原因而导致的海关扣货，此情况不在赔偿范围之内，我司只是协助发件人提供清关文件； 3）如因客户货物本身质量问题以及涉及到具体的认证问题等导致海关扣货，均不受理赔偿； 4）如遇战争，自然灾害等不可抗力因素导致货物破坏或灭失，不受理赔偿； 5）在运输过程中如遇到航班和船公司延误/清关延误等引起的总体时效延误，均不受理赔偿； 6）快递派运输途中因外包装破损导致产品缺失，我司可以协助调查，不在我司理赔范围内； 7）易碎品不接受任何损坏赔偿。 8）卡派过程中如果单箱丢失、少件、货损，我司可以协助调查，最终以卡车公司受理结果为准，不在我司赔偿范围内； 9）卡车POD上面没有签收产品破损具体件数/丢失具体件数/现场照片，我司不受理赔偿； 索赔期限及规则： 卡派索赔程序： a. 客户要在签收后7个工作日内告知我司，超过30个工作日未提供完整资料的，我司将不再接受理赔申请； b. 客户在索赔期间需要积极协助我司进行索赔，提供完整资料之后3个月，我司正常理赔给客人； 注：若逾期未提供完整相应索赔资料，则相应责任由客户自行承担，我司不再接受理赔申请。
A30: 特别提示：如客户一旦同意接受我司服务，我司将默认为客户已详细阅读过此价格表备注内容，并接受各条款的约束!

Sheet 美线商业卡车
A2: 上海至尊达CLX-卡派（全美非FBA卡派单询） 普货体积比 1:6000 币种：人民币 | F2: =美国海派包税!N7 -> 船期：06月24日
A3: 区域 | B3: 重量 | C3: 301+ | D3: 1001+ | E3: 2001+ | F3: 签收时效（自然日）
A4: 从我司CA 91761仓库送40 MILES以内商业地址（只适于常规尺寸的纸箱/托盘货物，LIFT GATE费用另计） | B4: 平泡 | C4: 12.116 | D4: 11.282717 | E4: 11.014493 | F4: 14-18天
B5: 1:200 | C5: 10.6757 | D5: 9.5703297 | E5: 9.0272864
B6: 1:250 | C6: 9.008 | D6: 8.178022 | E6: 7.7712144
B7: 1:300 | C7: 8.0156 | D7: 7.1866134 | E7: 6.6966517
A8: 上海美森限时达MAX-卡派（全美非FBA地址卡派单询） 普货体积比 1:6000 币种：人民币 | F8: =美国海派包税!N12 -> 船期：06月25日
A9: 区域 | B9: 重量 | C9: 301+ | D9: 1001+ | E9: 2001+ | F9: 签收时效（自然日）
A10: 从我司CA 91761仓库送40 MILES以内商业地址（只适于常规尺寸的纸箱/托盘货物，LIFT GATE费用另计） | B10: 平泡 | C10: 11.3 | D10: 10.467532 | E10: 10.198901 | F10: 16-18天
B11: 1:200 | C11: 9.9957 | D11: 8.891009 | E11: 8.3476262
B12: 1:250 | C12: 8.464 | D12: 7.6345654 | E12: 7.2274863
B13: 1:300 | C13: 7.5532 | D13: 6.7246753 | E13: 6.2412794
A14: 限时达统配-卡派（全美非FBA卡派单询） 普货体积比 1:6000 币种：人民币 | F14: =美国海派包税!N17 -> 船期：06月25日
A15: 区域 | B15: 重量 | C15: 301+ | D15: 1001+ | E15: 2001+ | F15: 签收时效（自然日）
A16: 从我司CA 91761仓库送40 MILES以内商业地址（只适于常规尺寸的纸箱/托盘货物，LIFT GATE费用另计） | B16: 平泡 | C16: 9.122 | D16: 8.2917083 | E16: 8.021989 | F16: 16-19天
B17: 1:200 | C17: 8.1807 | D17: 7.0778222 | E17: 6.5335332
B18: 1:250 | C18: 7.012 | D18: 6.184016 | E18: 5.7762119
B19: 1:300 | C19: 6.319 | D19: 5.4917083 | E19: 5.0258371
A20: 美西OA普船-卡派 （全美非FBA卡派单询） 普货体积比 1:6000 币种：人民币 | F20: =美国海派包税!N22 -> 船期：06月27日
A21: 区域 | B21: 重量 | C21: 301+ | D21: 1001+ | E21: 2001+ | F21: 签收时效（自然日）
A22: 从我司CA 91761仓库送40 MILES以内商业地址（只适于常规尺寸的纸箱/托盘货物，LIFT GATE费用另计） | B22: 平泡 | C22: 7.9 | D22: 7 | E22: 6.8 | F22: 22-25天
B23: 1:200 | C23: 7.2 | D23: 6.1 | E23: 5.5
B24: 1:250 | C24: 6.3 | D24: 5.5 | E24: 5
B25: 1:300 | C25: 5.8 | D25: 4.9 | E25: 4.5
A28: 美森至尊达，美森限时达，限时达统配，美东普船 货交深圳/青岛加0.7/KG； 美西OA普船 交青岛/深圳不加钱
B29: 产品附加费说明 | E29: 加收金额
A30: 1 | B30: 木制品/竹制品/等动植物制品，若不是报关件，需要加收额外附加费 (若是报关件不收此附加费，客户自行做商检，我司代办商检费实报实销） | E30: RMB1/KG MAX:RMB500
A31: 2 | B31: 钢/铝/铜制品及其衍生品（232-I-A） | E31: RMB1/KG
A32: 3 | B32: 鞋子/包/圆珠笔/服装/U盘/内存卡类产品 | E32: RMB1/KG
A33: 4 | B33: 反倾销品 | E33: 单独确认
A34: 操作说明
A35: 1 | B35: FBA货物每件货物需贴2个以上合格的FBA标签,在货物的外包装和单件货物上必须要有MADE IN CHINA。
A36: 2 | B36: 不接受易变形或太软的纸箱，如亚马逊仓库或其他收货仓库因包装问题或其他问题产生拒收等原因，破损丢件，我司不承担任何责任。
A37: 3 | B37: 目的地海关认定货物是品牌货物，或者是CE、蓝牙、HDMI、FDA、FCC、Lacey Act、DOT等认证的问题，或者货物属于当地反倾销,或不符合目的地国家进口要求的货物，客人需要提供相应授权书或认证报告，如果提供不了导致货物扣关甚至退运而产生的所有责任和相关费用将由发件人承担。
A38: 4 | B38: 此渠道不接仿牌、贵金属、侵权产品、危险品、成人用品、敏感品、儿童玩具类、违禁品、易燃易爆等明确规定的，特殊产品请单询。 如果瞒报发现冲货，永久终止合作不做解释，并承担由此产生的海关扣关罚款及连带责任！
A39: 5 | B39: 所有客户暂扣件及改派地址业务，我司不承诺百分百成功，如有此问题我司不承担任何赔偿。
A40: 6 | B40: 卡车赔偿标准： 1.理赔需要提供采购发票等相关资料，以便对货值的合理性进行评估； 2.在国际海运运输过程中如货物丢失，按RMB20/KG赔偿，退运费，最高不能超过货值； 3.卡车提取之后整托丢失的，按照USD500/托理赔，最高不能超过货值； 4.卡派货物请客户自己购买保险，否则只能按照我司赔偿标准。 特别申明以下情况不受理赔偿： 1）如因侵权/瞒报问题海关扣货，我司不承担任何责任并且保留追究发件人因此带来对我司的损失的赔偿； 2）如货物没有按照实际货物申报、当地禁止进口等原因而导致的海关扣货，此情况不在赔偿范围之内，我司只是协助发件人提供清关文件； 3）如因客户货物本身质量问题以及涉及到具体的认证问题等导致海关扣货，均不受理赔偿； 4）如遇战争，自然灾害等不可抗力因素导致货物破坏或灭失，不受理赔偿； 5）在运输过程中如遇到航班和船公司延误/清关延误等引起的总体时效延误，均不受理赔偿； 6）快递派运输途中因外包装破损导致产品缺失，我司可以协助调查，不在我司理赔范围内； 7）易碎品不接受任何损坏赔偿。 8）卡派过程中如果单箱丢失、少件、货损，我司可以协助调查，最终以卡车公司受理结果为准，不在我司赔偿范围内； 9）卡车POD上面没有签收产品破损具体件数/丢失具体件数/现场照片，我司不受理赔偿； 索赔期限及规则： 卡派索赔程序： a. 客户要在签收后7个工作日内告知我司，超过30个工作日未提供完整资料的，我司将不再接受理赔申请； b. 客户在索赔期间需要积极协助我司进行索赔，提供完整资料之后3个月，我司正常理赔给客人； 注：若逾期未提供完整相应索赔资料，则相应责任由客户自行承担，我司不再接受理赔申请。
A42: 特别提示：如客户一旦同意接受我司服务，我司将默认为客户已详细阅读过此价格表备注内容，并接受各条款的约束!

Sheet 空运价格
A2: 美国亚马逊空运UPS/FEDEX快线 双清含油包税
A3: （限时达）航班统配
A4: 区域/邮编 | B4: 重量 | D4: 12-20KG | E4: 21-100KG | F4: 101KG+ | G4: 最快提取时效
A5: 美西（邮编:8-9开头） | B5: 价格 | D5: 66 | E5: 62 | F5: 59 | G5: 货物入上海仓第二天起5-7个工作日提取，超出时效提取每工作日赔付1/kg，(提取当天不计算在内，免责列明情况除外） 1:300价格本减1/KG （比重只适用于100KG以上的货物）
A6: 美中（邮编:4-7开头） | B6: 价格 | D6: 69 | E6: 65 | F6: 62
A7: 美东（邮编:0-3开头） | B7: 价格 | D7: 70 | E7: 66 | F7: 63
A8: （极快达）上海航班统配-后端机场加急提货-优先交UPS
A9: 区域/邮编 | B9: 重量 | D9: 12-20KG | E9: 21-100KG | F9: 101KG+ | G9: 最快提取时效
A10: 美西（邮编:8-9开头） | B10: 价格 | D10: 72 | E10: 68 | F10: 65 | G10: 货物入上海仓第二天起2-4个工作日提取，超出时效提取按照限时达价格结算，其他延误标准参考限时达。（提取当天不计算在内，免责列明情况除外） 1:300价格本减1/KG （比重只适用于100KG以上的货物）
A11: 美中（邮编:4-7开头） | B11: 价格 | D11: 75 | E11: 71 | F11: 68
A12: 美东（邮编:0-3开头） | B12: 价格 | D12: 76 | E12: 72 | F12: 69
A13: 特别提示A： | B13: 运输的货物必须是相关法律法规允许流通的物品，托运人不得在托运的货物中夹带包括但不限于带磁、带电、易燃、易爆、有毒、有特殊气味货物及国家禁止进出口/限制进出口的物品及危险品，如隐瞒事实夹带前述货物而产生的一切责任、损失与费用（不限于罚款及给我公司造成的损失等）均由托运人承担。请如实申报！
A14: 特别提示B： | B14: 非FBA+1/KG（含0和1邮编）；报关费用统一350元/票；9710/9810监管方式报关+600/票 ；无安检清单/非危保函+20/票
A15: 二.有关附加费（包括但不限于以下列出产品，以实际货物在国外清关的难易度加收）附加费按计费重量收取
A16: 附加费特别说明 | F16: 加收金额 | G16: 备注
A17: 21KG以下包裹不接收一票多件,21KG以上一票多件包裹单件毛重不能低于10KG 不足10KG的重量按照10KG补收，不能超22kg累计计费. 派送类附加费
A18: 单件实重超过22kg；泡重超过31kg | F18: $35.5/件（重复叠加） | G18: 超重费
A19: 最长边超过120cm；第二边长超过75cm；周长超过260cm：长+[（2 x宽+2 x高）] | F19: $35.5/件（重复叠加） | G19: 超长费
A20: 未完全用瓦楞纸板包裹的任何物品，包括但不限于金属；木材，硬塑料，软塑料（如塑料袋） 或发泡聚苯乙烯泡沫（如聚苯乙烯泡沫塑料）； 未完全用波纹包装的任何圆柱形物品，如桶、鼓、桶或轮胎。 | F20: $30.5/件（重复叠加） | G20: 异形包装费
A21: 实际重量超过40kg；最长边长度超过243cm；周长超过325cm：长+[（2 x宽+2 x高）] | F21: $240/件（重复叠加） | G21: 超大包裹费
A22: 本渠道服务仅限于美国本土48洲,不接收邮箱BOX,军方地址,(不接收邮编：006-009 PUERTO RICO AND VIRGIN LSLANDS 波多黎各、维尔京群岛，966-969 HAWAIIAND GUAM 夏威夷、关岛 995-999 ALASKA 阿拉斯加等！)偏远以我司客服查询为准 | F22: $5.9/件 最低$29.5/票 | G22: 偏远费
A23: 更改地址费（包括更改，拦截，退回发件地址） | F23: $28/件（不保证100%更改成功） | G23: 更改地址费
F24: $3/件 | G24: POD签收单
A25: 物资等单独咨询； 单票物资附加费最低500元/票，物资需要单独报关500元/票； | F25: 最低500元/票， 物资需要单独报关500元/票；
A26: 磁检 | F26: +1元/kg或20元/件 | G26: 最低100元一票
A27: 木制品； 以下FDA产品：眼镜(太阳眼镜、近视眼镜、远视眼镜),需要提供FDA资料和滴珠证明； | F27: 附加费 +1/KG
A28: 单票超出5个品名 | F28: 附加费+50/个
A29: 托盘/木箱货 | F29: 附加费+5/KG
A30: 成人用品 反倾销产品 | F30: 附加费+3/KG
A31: 金属纪念币 | F31: 附加费+2/KG
A32: 儿童产品 | F32: 有CPSC+1/KG，无+3/KG； | G32: 有CPSC+1/KG，无+3/KG；
A33: 高货值产品 | F33: 加2-5元/KG不等 | G33: 带少量液体、玩具类产品、膏体等敏感类产品走货前单独咨询业务单独报价，未有单独报价我司财务默认按照最高者收取。
A34: 1.以上附加费最终以UPS/FEDEX账单为准，如目的国有额外费用产生一律由托运人承担。
A35: 2.货物件数、体积、重量、收费重量与实际货物入仓数据有差异的，则以实际货物入仓数据为准据实结算，贵司应自接到我公司通知之日起X日内及时补足差额，否则我公司有权拒绝贵司的委托 事项；因贵司怠于补足相应款项而导致出运延迟、报关延误、航班配载延期、价格调整等风险和损失均由贵司自行承担。
A36: 三、出口注意事项
A37: 1.托运人需如实向海关申报，如因申报品名不符或申报价值过低被海关扣留而导致产生的仓租及罚款由托运人承担。
A38: 2.美国海关认定货物是品牌货物或者如CE.蓝牙.HDMI/FDA/FCC/LACEYACT/DOT(不限于以上列举）等需认证的货物（参考表四）或者不符合美国进口要求的货物，托运人应于发货前提供相应授权书或者认证报告，如未提供导致货物扣关甚至退运而产生额外费用，由托运人承担。（提供报告或者授权，海关认定报告或授权予实物不符或者是虚假，不合格，导致货物扣关甚至退运而产生额外费用，由托运人承担）
A39: 3.如因目的地国家或地区严禁进口的货物（参考表二）或发件方/收件方提供清关资料不准确或不完备等原因引起的清关延误或货物禁止进口导致退回的，因此产生仓租费，退回运费等杂费以及因此引起相关责任一律由托运人支付和承担
A40: 四、拒收货物(参考《禁运表》《反倾销目录》)
A41: 五、免责 因货物自身原因、海关信息认定、查验、扣关、航班延误、航空管制、品牌授权或认证报告不符合当地标准、清关失败或不可抗力等非我公司原因造成的延迟、货损或货物销毁，我公司不承担赔偿责任。
...

Sheet 加拿大TOR商卡分区表
A1: 加拿大TOR商卡分区表
A2: Zone1 | B2: Zone2 | C2: Zone3 | D2: Zone4 | E2: Zone5 | F2: Zone6 | G2: Zone7 | H2: Zone8 | I2: Zone9 | J2: Zone10 | K2: Zone11 | L2: Zone12 | M2: Zone13 | N2: Zone14 | O2: Zone15
A3: BRAMPTON-ON | B3: Markham-ON | C3: Ajax-ON | D3: Caledon-ON | E3: ARISS-ON | F3: AILSA CRAIG-ON | G3: ACTON VALE-QC | H3: ALMA-QC | I3: ALMA-NB | J3: ATHOLVILLE-NB | K3: ALBANEL-QC | L3: ABBOTSFORD-BC | M3: BELFAST-PE | N3: ARNOLDS COVE-NL | O3: BAY ROBERTS-NL
A4: MISSISSAUGA-ON | B4: Oakville-ON | C4: Aurora-ON | D4: East Gwillimbury-ON | E4: ARVA-ON | F4: ALLANBURG-ON | G4: ALEXANDRIA-ON | H4: AMOS-QC | I4: AMHERST-NS | J4: BELCOURT-QC | K4: BEECHVILLE-NS | L4: ALBION-PE | M4: BRANDON-MB | N4: BAIE VERTE-NL | O4: BLIND BAY-BC
B5: Richmond Hill-ON | C5: Burlington-ON | D5: Belfountain-ON | E5: BADEN-ON | F5: AMHERSTBURG-ON | G5: WINDSOR-QC | H5: ASBESTOS-QC | I5: ANGLIERS-QC | J5: BON-CONSEIL-QC | K5: BOLTON-EST-QC | L5: AMQUI-QC | M5: CAUSAPSCAL-QC | N5: BAY BULLS-NL | O5: BLOOMFIELD-NL
B6: Downtown Toronto-ON | C6: HALTON HILLS-ON | D6: Blackstocak-ON | E6: BEAMSVILLE-ON | F6: ANGUS-ON | G6: ANJOU-QC | H6: BAIE-COMEAU-QC | I6: ARMAGH-QC | J6: BROOKLYN-NS | K6: CANTON TREMBLAY-QC | L6: ANNAPOLIS ROYAL-NS | M6: CHAMBERLAIN SETTLEMENT-NB | N6: BONAVISTA-NL | O6: BOTWOOD-NL
B7: Vaughan-ON | C7: King City-ON | D7: Bolton-ON | E7: BELLEVILLE-ON | F7: APPLE HILL-ON | G7: BAIE-D'URFÉ-QC | H7: BEAUCEVILLE-QC | I7: BANCROFT-ON | J7: BROWNSBURG-CHATHAM-QC | K7: DAWSON SETTLEMENT-NB | L7: YARMOUTH-NS | M7: CHANDLER-QC | N7: CARBONEAR-NL | O7: CHASE-BC
B8: North York-ON | C8: Milton-ON | D8: Caledon Village-ON | E8: BELMONT-ON | F8: ARNPRIOR-ON | G8: BATISCAN-QC | H8: BOISCHATEL-QC | I8: BATHURST-NB | J8: BURNABY-BC | K8: DELEAGE-QC | L8: ANTIGONISH-NS | M8: CHARTERS SETTLEMENT-NB | N8: CLAIRMONT-AB | O8: COCHENOUR-ON
B9: Concord-ON | C9: Newmarket-ON | D9: Cedar Valley-ON | E9: BINBROOK-ON | F9: ATWOOD-ON | G9: BEACONSFIELD-QC | H9: BONFIELD-ON | I9: BLACKVILLE-NB | J9: CACHE BAY-ON | K9: DELISLE-SK | L9: ASPHODEL-NORWOOD-ON | M9: CLARKS HARBOUR-NS | N9: CLARENVILLE-NL | O9: COLEY'S POINT-NL
B10: Etobicoke-ON | C10: Oshawa-ON | D10: Cheltenham-ON | E10: BLACKSTOCK-ON | F10: AUBURN-ON | G10: BEAUHARNOIS-QC | H10: BRIGHAM-QC | I10: BRIGHT'S GROVE-ON | J10: CHIBOUGAMAU-QC | K10: DESCHAILLONS-SUR-SAINT-LAURENT-QC | L10: AYLESFORD-NS | M10: DALHOUSIE-NB | N10: COCHRANE-AB | O10: CONCEPTION BAY SOUTH-NL
B11: Scarborough-ON | C11: Pickering-ON | D11: Goodwood-ON | E11: CAESAREA-ON | F11: BALA-ON | G11: BEAUPRE-QC | H11: BROMONT-QC | I11: WATERVILLE-QC | J11: CLERMONT-QC | K11: DOURO-DUMMER-ON | L11: BAIE-SAINTE-ANNE-NB | M11: DUFFIELD-AB | N11: CORNER BROOK-NL | O11: DOYLES-NL
B12: York-ON | C12: Whitby-ON | D12: Greenbank-ON | E12: CAMPBELLFORD-ON | F12: BELLE RIVER-ON | G12: BECANCOUR-QC | H12: BURKS FALLS-ON | I12: CACOUNA-QC | J12: DELTA-BC | K12: EASTMAN-QC | L12: BAKER BROOK-NB | M12: DUNLOP-NB | N12: ESTEVAN-SK | O12: GERALDTON-ON
B13: Woodbridge-ON | C13: Stouffville-ON | D13: Holland Landing-ON | E13: CARLISLE-ON | F13: BELWOOD-ON | G13: BELOEIL-QC | H13: CARIGNAN-QC | I13: CALGARY-AB | J13: DIEPPE-NB | K13: FERLAND-ET-BOILLEAU-QC | L13: BALTIC-PE | M13: FALL RIVER-NS | N13: GAMBO-NL | O13: GRAND BANK-NL
B14: Thornhill-ON | C14: Acton-ON | D14: Leaskdale-ON | E14: CLARKSBURG-ON | F14: BLUE MOUNTAINS-ON | G14: BLAINVILLE-ON | H14: WICKHAM-QC | I14: CAMPBELLTON-NB | J14: DOLBEAU-MISTASSINI-QC | K14: GORE-QC | L14: BANGOR-PE | M14: FISHER'S GRANT-NS | N14: GANDER-NL | O14: GRAND MANAN-NB
B15: Central Toronto-ON | C15: Ashburn-ON | D15: Mount Albert-ON | E15: COLLINGWOOD-ON | F15: BRINSTON-ON | G15: BOISBRIAND-QC | H15: CHARLTON-ON | I15: CAP-CHAT-QC | J15: DUPARQUET-QC | K15: GRAND-BARACHOIS-NB | L15: BARR SETTLEMENT-NS | M15: FIVE ISLANDS-NS | N15: GOULDS-NL | O15: HAPPY VALLEY-GOOSE BAY-NL
B16: West Toronto-ON | C16: Brooklin-ON | D16: Palgrave-ON | E16: COMBERMERE-ON | F16: BROCKVILLE-ON | G16: BOIS-DES-FILION-QC | H16: CHATEAU-RICHER-QC | I16: CHATHAM-NB | J16: ELK LAKE-ON | K16: GRANDES-PILES-QC | L16: BARRYS BAY-ON | M16: FORESTVILLE-QC | N16: GRAND FALLS-NL | O16: HARBOUR BRETON-NL
... B23: Locust Hill-ON | C23: Pickering (Cherrywood)-ON | D23: Uxbridge-ON | E23: FONTHILL-ON | F23: CHESTERVILLE-ON | G23: CHATEAUGUAY-ON | H23: CURRAN-QC | I23: EDMUNDSTON-NB | J23: LANTIER-QC | K23: LAC-DES-PLAGES-QC | L23: BOUCTOUCHE-NB | M23: HOPEWELL-NS | N23: LONG COVE-NL | O23: MEDICINE HAT-AB
B24: Markham (Milliken)-ON | C24: Pickering (Claremont)-ON | E24: GRAFTON-ON | F24: CLINTON-ON | G24: CHELMSFORD-ON | H24: DAVELUYVILLE-QC | I24: FRANKVILLE-ON | J24: LAROUCHE-QC | K24: LAC-DES-ÎLES-QC | L24: BOWMAN-QC | M24: IRISHTOWN-NB | N24: LOURDES-NL | O24: MOUNT PEARL-NL
B25: Oak Ridges-ON | C25: Schomberg-ON | E25: GRANTON-ON | F25: COBOURG-ON | G25: COATICOOK-QC | H25: DEEP RIVER-ON | I25: FREDERICTON-NB | J25: LES ESCOUMINS-QC | K25: LATERRIERE-QC | L25: BRIDGETOWN-NS | M25: IROQUOIS FALLS-ON | N25: MOOSOMIN-SK | O25: NANAIMO-BC
E26: HAGERSVILLE-ON | F26: COLBORNE-ON | G26: COOKSHIRE-QC | H26: DOLBEAU-QC | I26: GAGETOWN-NB | J26: LES LAURENTIDES REGIONAL COUNTY-QC | K26: LOCHABER-QC | L26: BRIDGEWATER-NS | M26: KAPUSKASING-ON | N26: MUSGRAVE HARBOU-NL | O26: NORRIS ARM-NL
E27: HALIBURTON-ON | F27: COLDWATER-ON | G27: CORNWALL-ON | H27: DUMORE-QC | I27: GRACEFIELD-QC | J27: LONGUE-RIVE-QC | K27: MAHONE BAY-NS | L27: BRUNSWICK-NB | M27: MADELEINE-CENTRE-QC | N27: NIPIGON-ON | O27: PENTICTON-BC
E28: ILDERTON-ON | F28: CORUNNA-ON | G28: COTE SAINT-LUC-QC | H28: EAST ANGUS-QC | I28: GRAND FALLS-NB | J28: MASSEY-ON | K28: MASHTEUIATSH-QC | L28: CANNING-NS | M28: MAZEROLLE SETTLEMENT-NB | N28: PARADISE-NL | O28: PETIT-ROCHER-NORD-NB
E29: JANETVILLE-ON | F29: COTTAM-ON | G29: COTEAU-DU-LAC-QC | H29: ESPANOLA-ON | I29: HAM-SUD-QC | J29: METABETCHOUAN-LAC-A-LA-CROIX-QC | K29: MATTAWA-ON | L29: CANSO-NS | M29: MEMBERTOU-NS | N29: PLACENTIA-NL | O29: SOUTH BAR-NS
E30: KAWARTHA LAKES-ON | F30: CREEMORE-ON | G30: COWANSVILLE-QC | H30: GODMANCHESTER-QC | I30: HARTLAND-NB | J30: MONT-BLANC-QC | K30: MEMRAMCOOK-NB | L30: CAVENDISH-PE | M30: MILTON STATION-PE | N30: PORT AU CHOIX-NL | O30: ST LAWRENCE-NL
E31: KOMOKA-ON | F31: DORCHESTER-ON | G31: DELSON-QC | H31: GORE BAY-ON | I31: HILLSBOROUGH-NB | J31: NANTES-QC | K31: NAPAN-NB | L31: CHARLOTTETOWN-PE | M31: MISCOUCHE-PE | N31: PORT AUX BASQUE-NL | O31: SYDNEY FORKS-NS
E32: LETHBRIDGE COUN-ON | F32: DRESDEN-ON | G32: DEUX-MONTAGNES-QC | H32: GRANBY-QC | I32: HOWICK-QC | J32: NEDELEC-QC | K32: NOTRE-DAME-DES-SEPT-DOULEURS-QC | L32: CHETICAMP-NS | M32: MUSQUASH-NB | N32: POUCH COVE-NL | O32: TERRACE-BC
E33: LINCOLN-ON | F33: DUNSFORD-ON | G33: DOLLARD-DES-ORMEAUX-QC | H33: GRAVENHURST-ON | I33: KEDGWICK-NB | J33: NEW WESTMINSTER-BC | K33: NOTRE-DAME-DU-PORTAGE-QC | L33: CHILLIWACK-BC | M33: NEW ROSS-NS | N33: RED DEER-AB | O33: VICTORIA-BC
E34: LINWOOD-ON | F34: DURHAM-ON | G34: DONNACONA-QC | H34: HAGAR-ON | I34: LA BAIE-QC | J34: NORTH GOWER-ON | K34: RAMARA-ON | L34: COQUITLAM-BC | M34: NIGADOO-NB | N34: REGINA-SK | O34: WHEATLEY RIVER-PE
E35: LONDON-ON | F35: ELMIRA-ON | G35: DORVAL-QC | H35: HEARST-ON | I35: LAMBTON-QC | J35: NOTRE-DAME-DE-LA-PAIX-QC | K35: RAMORE-ON | L35: CURRYS CORNER-NS | M35: OGDEN-QC | N35: RIMBEY-AB | O35: WHISTLER-BC
E36: MITCHELL-ON | F36: EMBRUN-ON | G36: DRUMMONDVILLE-QC | H36: HIGHLAND GROVE-QC | I36: LATCHFORD-QC | J36: ORFORD-QC | K36: ROCKY VIEW COUNTY-AB | L36: DARTMOUTH-NS | M36: OTTER LAKE-QC | N36: SAINT-NARCISSE-DE-RIMOUSKI-QC
E37: MOUNT BRYDGES-ON | F37: ESSEX-ON | G37: GALLICHAN-QC | H37: HUDSON-QC | I37: LAURIER-STATION-QC | J37: PERCE-QC | K37: ROGERSVILLE-EST-NB | L37: DEGELIS-QC | M37: PETIT-SAGUENAY-QC | N37: SASKATOON-SK
E38: NAPANEE-ON | F38: EVERETT-ON | G38: GATINEAU-QC | H38: HUNTSVILLE-ON | I38: LAVALTRIE-QC | J38: PETITE-RIVIERE-SAINT-FRANCOIS-QC | K38: SAINT ANDREWS-QC | L38: DEVON-AB | M38: PORT MAITLAND-NS | N38: SPRINGDALE-NL
E39: NEW HAMBURG-ON | F39: EXETER-ON | G39: GREENFIELD PARK-QC | H39: IRON BRIDGE-ON | I39: LITTLE CURRENT-ON | J39: PIEDMONT-QC | K39: SAINT-ADOLPHE-D'HOWARD-QC | L39: DIGBY-NS | M39: PORT WILLIAMS-NS | N39: STEPHENVILLE-NL
E40: NIAGARA FALLS-ON | F40: FIELD-ON | G40: GRONDINES-QC | H40: JOLIETTE-QC | I40: LOWER SACKVILLE-NS | J40: PONT-ROUGE-QC | K40: THREE FATHOM HARBOUR-NS | L40: DRYDEN-ON | M40: PRINCE GEORGE-BC | N40: SUMMERVILLE-NL
E41: NIAGARA ON THE LAKE-ON | F41: FLESHERTON-ON | G41: HAMPSTEAD-QC | H41: KIRKFIELD-ON | I41: MALARTIC-QC | J41: PORT-CARTIER-QC | K41: SAINT-ALBAN-QC | L41: DUNDEE-NB | M41: RICHIBUCTO ROAD-NB | N41: SUNNYBROOK-AB
E42: PENETANGUISHENE-ON | F42: FORMOSA-ON | G42: HARRINGTON-QC | H42: LA MALBAIE-QC | I42: MASSUEVILLE-QC | J42: RICHMOND-BC | K42: SAINT-AMBROISE-DE-KILDARE-QC | L42: EASTERN PASSAGE-NS | M42: ROBERTVILLE-NB | N42: TORBAY-NL
E43: PETERBOROUGH-ON | F43: FORT ERIE-ON | G43: HAWKESBURY-ON | H43: LA SARRE-QC | I43: MCADAM-NB | J43: RIMOUSKI-QC | K43: SAINT-ANDRE-AVELLIN-QC | L43: ELMSDALE-NS | M43: SAINT-ANDRE-NB | N43: TREPASSEY-NL
E44: PONTYPOOL-ON | F44: FRANKFORD-ON | G44: HEMMINGFORD-QC | H44: LA TUQUE-QC | I44: MILLE-ISLES-QC | J44: SAINT JOHN-NB | K44: SAINT-ANDRE-DE-KAMOURASKA-QC | L44: ENFIELD-NS | M44: SAINT-FELIX-D'OTIS-QC | N44: TWILLINGATE-NL
E45: PORT CARLING-ON | F45: GANANOQUE-ON | G45: KAHNAWAKE-QC | H45: LAC ETCHEMIN-QC | I45: MILLVILLE-NB | J45: SAINT-ALPHONSE-DE-GRANBY-QC | K45: SAINT-CAMILLE-QC | L45: ESCUMINAC-QC | M45: ST. JOHN'S-NL | N45: WABUSH-NL
E46: ALLISTON-ON | F46: GILFORD-ON | G46: KIRKLAND-QC | H46: LAC MEGANTIC-QC | I46: MONCTON-NB | J46: SAINT-ALPHONSE-RODRIGUEZ-QC | K46: SAINTE-ANNE-DE-LA-POCATIERE-QC | L46: FOX BROOK-NS | M46: SAINT-ROCH-DES-AULNAIES-QC | N46: Upper Brookside-NB
...

Sheet 加拿大CAL商卡分区表
A1: 加拿大CAL商卡分区表
A2: Zone1 | B2: Zone2 | C2: Zone3 | D2: Zone4 | E2: Zone5 | F2: Zone6 | G2: Zone7 | H2: Zone8 | I2: Zone9 | J2: Zone10 | K2: Zone11 | L2: Zone12 | M2: Zone13 | N2: Zone14
A3: CALGARY-AB 201 LINE | B3: ALDERSYDE-AB | C3: RED DEER-AB | D3: SHERWOOD PARK-AB | E3: WINNIPEG-MB | F3: PENTICTON-BC | G3: NANAIMO-BC | H3: ANGUS-ON | I3: ST JEROME-QC | J3: FLIN FLON-MB | K3: LAC ETCHEMIN-QC | L3: HALIFAX-NS | M3: LOUISBOURG-NS | N3: PLACENTIA-NL
B4: AIRDRIE-AB | C4: COCHRANE-AB | D4: ST ALBERT-AB | E4: SASKATOON-SK | F4: WHISTLER-BC | G4: VICTORIA-BC | H4: TORONTO-ON | I4: FORT ERIE-ON | J4: PROCTER-BC | K4: SOREL-QC | L4: SHERBROOKE-NS | M4: CORNER BROOK-NL | N4: TREPASSEY-NL
B5: HIGH RIVER-AB | C5: MEETING CREEK-AB | D5: STAR-AB | E5: MITCHELL-MB | F5: ESTEVAN-SK | G5: PRINCE GEORGE-BC | H5: MILTON-ON | I5: GODERICH-ON | J5: HUDSON BAY-SK | K5: BATISCAN-QC | L5: STEWIACKE-NS | M5: STEPHENVILLE-NL | N5: CLARENVILLE-NL
B6: OKOTOKS-AB | C6: BANFF-AB | D6: CAMROSE-AB | E6: WINKLER-MB | F6: BROADVIEW-SK | G6: VANDERHOOF-BC | H6: OAKVILLE-ON | I6: GRIMSBY-ON | J6: STRATHCLAIR-MB | K6: THETFORD MINES-QC | L6: BRIDGEWATER-NS | M6: LOURDES-NL | N6: ARNOLDS COVE-NL
C7: STETTLER-AB | D7: LETHBRIDGE-AB | E7: REGINA-SK | F7: FORGET-SK | G7: PORT ALBERNI-BC | H7: NEWMARKET-ON | I7: LISTOWEL-ON | J7: MORSE-SK | K7: CHICOUTIMI-QC | L7: KENTVILLE-NS | M7: GRAND FALLS-NL | N7: SUMMERVILLE-NL
C8: SYLVAN LAKE-AB | D8: COALDALE-AB | E8: KAMLOOPS-BC | F8: MERRITT-BC | G8: QUESNEL-BC | H8: AJAX-ON | I8: LONDON-ON | J8: MAPLE CREEK-SK | K8: DOLBEAU-QC | L8: SHEET HARBOUR-NS | M8: PORT AUX BASQUE-NL | N8: BONAVISTA-NL
C9: EDMONTON-AB | D9: EVANSBURG-AB | E9: KELOWNA-BC | F9: STONEWALL-MB | G9: MCBRIDE-BC | H9: OSHAWA-ON | I9: SARNIA-ON | J9: MINITONAS-MB | K9: ASBESTOS-QC | L9: ELMSDALE-NS | M9: GANDER-NL | N9: MARYSTOWN-NL
C10: FOOTHILLS-AB | D10: MEDICINE HAT-AB | E10: VANCOUVER-BC | F10: STONY PLAIN-AB | G10: NORTH SAANICH-BC | H10: HANOVER-ON | I10: SIMCOE-ON | J10: ALIX-AB | K10: ALMA-QC | L10: CHARLOTTETOWN-PE | M10: PORT AU CHOIX-NL | N10: GRAND BANK-NL
C11: BROOKS-AB | D11: KIMBERLEY-AB | E11: FORT MCMURRAY-AB | F11: GRUNTHAL-AB | G11: SMITHERS-BC | H11: BARRIE-ON | I11: ST CATHARINES-ON | J11: DELMAS-SK | K11: EDMUNDSTON-NB | L11: SUMMERSIDE-PE | M11: SPRINGDALE-NL | N11: HARBOUR BRETON-NL
C12: BRUCE-AB | D12: LONGVIEW-AB | E12: ROSTHERN-SK | F12: KLEEFELD-MB | G12: DUNCAN-BC | H12: BOWMANVILLE-ON | I12: STRATHROY-ON | J12: WILKIE-SK | K12: HARTLAND-NB | L12: CANSO-NS | M12: GAMBO-NL | N12: SOUTH INDIAN LAKE-MB
C13: LEDUC-AB | E13: BATTLEFORD-SK | F13: MOOSE JAW-AB | G13: SIDNEY-BC | H13: ORANGEVILLE-ON | I13: TILLSONBURG-ON | J13: HUGHENDEN-AB | K13: LOUISEVILLE-QC | L13: NEW GLASGOW-NS | M13: TWILLINGATE-NL
C14: ROCKY VIEW COUNTY-AB | E14: PRINCE ALBERT-SK | F14: ST BRIEUX-SK | G14: SMITHERS-BC | H14: ORILLIA-ON | I14: WOODSTOCK-ON | J14: RANDOLPH-MB | K14: LA TUQUE-QC | L14: TRURO-NS | M14: BAIE VERTE-NL
C15: NISKU-AB | E15: ABBOTSFORD-BC | F15: DEVON-AB | G15: ERRINGTON-BC | H15: OWEN SOUND-ON | I15: JOLIETTE-QC | J15: SNNYBROOKU-AB | K15: ST FRANCOIS DE-NB | L15: ANTIGONISH-NS | M15: MUSGRAVE HARBOU-NL
C16: RED DEER COUNTY-AB | E16: MARA-BC | F16: CREMONA-AB | G16: POWELL RIVER-BC | H16: LINDSAY-ON | I16: L'ASSOMPTION-QC | J16: LANDIS-SK | K16: MILLVILLE-NB | L16: TIGNISH-PE | M16: LA SCIE-NL
C17: STRATHMORE-AB | E17: MORDEN-MB | F17: LAKE COUNTRY-BC | G17: CAMPBELL RIVER-BC | H17: COBOURG-ON | I17: CORNWALL-ON | J17: ST ADOLPHE-MB | K17: ROBERVAL-QC | L17: TATAMAGOUCHE-NS | M17: ST JOHNS-NL
E18: RICHMOND-BC | F18: WEST VANCOUVER-BC | G18: PARKSVILLE-BC | H18: PETERBOROUGH-ON | I18: KEMPTVILLE-ON | J18: GRANDE CACHE-AB | K18: GRAND FALLS-NB | L18: GASPE-QC | M18: POUCH COVE-NL
E19: DAUPHIN-MB | G19: PENDER ISLAND-BC | H19: MONTREAL-QC | I19: KINGSTON-ON | J19: WABASCA-AB | K19: KEDGWICK-NB | L19: MATAPEDIA-QC | M19: BAY BULLS-NL
E20: DELTA-BC | G20: DAWSON CREEK-BC | H20: STE THERESE BLA-QC | I20: ST JEAN SUR RIC-QC | J20: EAST SELKIRK-MB | K20: LAC MEGANTIC-QC | L20: NEW RICHMOND-QC | M20: HARBOUR MAIN-NL
E21: MINNEDOSA-MB | G21: COURTENAY-BC | H21: SALABERRY-DE-VALLEYFIELD-QC | I21: BRANTFORD-ON | J21: DRUMHELLER-AB | K21: FREDERICTON-NB | L21: PORT HAWKESBURY-NS | M21: CARBONEAR-NL
E22: REINFELD-MB | G22: ARBORG-MB | H22: MELFORT-SK | I22: WINDSOR-ON | J22: STEINBACH-MB | K22: SAINT JOHN-NB | L22: YARMOUTH-NS | M22: LONG COVE-NL
E23: SURREY-BC | G23: STE ROSE DU LAC-MB | H23: PEACE RIVER-AB | I23: CAMBRIDGE-ON | J23: INVERMERE-BC | K23: TRACY-NB | L23: SHELBURNE-NS | M23: LINTLAW-SK
E24: VERNON-BC | G24: MADEIRA PARK-BC | H24: CARIBOO HWY-BC | I24: GUELPH-ON | J24: LOWER NICOLA-BC | K24: GAGETOWN-NB | L24: DIGBY-NS | M24: NORWAY HOUSE-MB
E25: BRANDON-MB | G25: WESTEROSE-AB | H25: ZENON PARK-SK | I25: ELMIRA-ON | K25: CHIPMAN-NB | L25: LIVERPOOL-NS
E26: LOCKPORT-MB | G26: DIDSBURY-AB | H26: TRAIL-BC | I26: HAMILTON-ON | K26: MCADAM-NB | L26: MIDDLETON-NS
E27: COQUITLAM-BC | G27: NANOOSE BAY-BC | H27: MUNDARE-AB | I27: OTTAWA-ON | K27: DOAKTOWN-NB | L27: SYDNEY-NS
E28: LLOYDMINSTER-AB | G28: KIMBERLEY-BC | H28: LYALTA-AB | I28: DRUMMONDVILLE-QC | K28: MONCTON-NB | L28: INGONISH-NS
E29: SILTON-SK | G29: NAROL-MB | H29: FORT QU'APPELLE-SK | I29: BELLEVILLE-ON | K29: ST STEPHEN-NB | L29: INVERNESS-NS
E30: MAPLE RIDGE-BC | G30: FORT MACLEOD-AB | H30: REDCLIFF-AB | I30: BROCKVILLE-ON | K30: SHEDIAC-NB | L30: CHETICAMP-NS
E31: KEREMEOS-BC | G31: CLARESHOLM-AB | H31: LAC LA BICHE-AB | I31: LEAMINGTON-ON | K31: SACKVILLE-NB | L31: THOMPSON-MB
E32: MARSDEN-SK | G32: LACOMBE-AB | H32: KELSEY-AB | I32: PORTNEUF-QC | K32: PETITCODIAC-NB | L32: LAC LABICHE-AB
E33: NEW WESTMINSTER-BC | G33: STE ANNE-MB | H33: KYLE-SK | I33: QUEBEC CITY-QC | K33: AMHERST-NS | L33: COCHENOUR-MB
E34: COLDSTREAM-BC | G34: PICTURE BUTTE-AB | H34: LIBAU-MB | I34: ACTON VALE-QC | K34: PORT ELGIN-NB | L34: MIDDLEBRO-MB
E35: KERROBERT-SK | G35: IRRICANA-AB | H35: MACGREGOR-MB | I35: SMITHS FALLS-ON | K35: RICHIBUCTO-NB | L35: SOURIS-MB
E36: DAVIDSON-SK | G36: RM OF SHERWOOD-SK | H36: GERALD-SK | I36: ST HYACINTHE-QC | K36: SPRINGHILL-NS | L36: BALMORAL-MB
... E46: LORETTE WEST-MB | G46: SPRUCE GROVE-AB | H46: STURGIS-MB | I46: ARNPRIOR-ON | K46: BLACKVILLE-NB | L46: UNION BAY-BC
E47: FORGET-SK | H47: MILESTONE-SK | I47: COATICOOK-QC | K47: MATANE-QC
E48: WESTBANK-BC | H48: DUMORE-AB | I48: ST GEORGES-QC | K48: SUTTON WEST-MB
E49: PORTAGE LA PRAIRIE-MB | H49: HANNA-AB | I49: STE MARIE (BEAU-QC | K49: BURR-SK
...

Sheet 禁运反倾销及特殊监管表
A1: 禁运品反倾销及特殊监管产品
M2: 返回目录
A3: 全球禁止入仓的货物
A4: 根据《国际海运危险货物规则》和国家标准《危险货物品名表》所列的危险品，目前，我司仓库不接收的货物品名如下（包括但不限于以下品名）：
A5: (1)爆炸品：炸药、雷管、火药、子弹、烟花、鞭炮等；
A6: (2)易燃气体：打火机、打火机油、空气清新剂、摩丝(发胶、头发定型剂)、液化气，灭火器等；
A7: (3)易燃液体：油漆、酒精、白酒、胶黏剂、粘合剂、丙酮、汽油、柴油、天那水、胶水、 粘合剂、油墨、定型水、指甲油、香水等；
A8: (4)易燃固体：火柴、硫磺、明胶、硝基、磷、镁、乒乓球、蜡烛等；
A9: (5)毒性物质：砷、尼古丁、氰化物、氰化钾、杀虫剂、农药等；
A10: (6)腐蚀品：硫酸、盐酸、氢氧化钠、氢氧化钾、水银、双氧水、电镀用溶液、蓄电池、清洗液、清洁水等；
A11: (7)杂类：安全气囊、太阳能移动电源、字画、古玩，二手物品等；
A12: (8)仿牌类：凡是在中国海关和其他国家/地区海关网站上能查到登记信息的任何仿牌货物都禁止入仓，非牌子货需提供品牌申明书；
A13: 其他限制入仓货物：不属于以上危险品目录范围的货物以及其它外包装上带有易燃、 易爆、易腐蚀标示的货物等，请在交货时提供产品说明、MSDS及保函（审批后确认是否可以入仓）。
A14: 美国反倾销产品目录
A15: (1)贱金属及其制品 | C15: 钢钉、钢管、碳合金钢丝条、金属硅、金刚石锯片、不锈钢货架、不锈钢加压管、定尺碳素钢板、石油专用管材、冷轴碳钢、薄壁矩形钢管、熨衣架及部件、螺纹钢筋、弹簧垫圈、非封闭内置弹簧部件、不锈钢拉制深水槽、冷轧钢板、无缝碳钢和合金钢标准管、管线管和压力管、圆锥滚子轴承、铸铁件、金属镁、镀锌板、重锻造手动工具（斧子、撬杠、锤子、镐头）、钢制高压气瓶
A16: (2)化学产品 | C16: 己内酰胺（又称碳酸锂）、聚对苯二甲酸乙二酯膜片和条、聚乙烯醇、高锰酸钾、三聚氰胺、天然猪鬃油漆刷及刷头
A17: (3)杂项制品 | C17: 木制卧室家具、复合木地板、硬木胶合板产品，非晶硅织物、晶体硅光伏电池、小直径石墨电极
A18: (4)机械电气设备及部件 | C18: 滚球轴承、汽车挡风玻璃、刹车鼓与刹车转子，轮毂，轮胎
A19: (5)纸及纸制品 | C19: 铜版纸、格记录纸、薄绵纸、折叠礼品盒、皱纹纸、无涂层纸，低克重热敏纸
A20: (6)纺织制品 | C20: 聚酯纤维、画布、编织电热毯，原聚酯棉印花布，窄幅梭织缎带
A21: (7)预制食品与饮料 | C21: 淹渍蘑菇罐头、柠檬酸与柠檬酸盐、华糖醇、冷冻的和罐装的暖水虾
A22: (8)塑料与橡胶制品 | C22: 复合编织袋、聚乙烯手提袋、新充气工程机械轮胎
A23: (9)日常生活用品 | C23: 折叠金属椅子，搪瓷厨具，钢丝衣架，蜡烛（所有石蜡制品），曲别针，铅笔
A24: (10)家用电器 | C24: 彩色电视机、家用大型洗衣机
A25: (11)车船运输设备及部件 | C25: 自行车、手推车
A26: (12)建材与玻璃制品 | C26: 铝型材、双轴土工格栅、镁碳砖
A27: (13)蔬菜产品 | C27: 蜂蜜
A30: 美国特殊监管产品
A31: (1) FDA 食品和药物管理局 食品，药品，医疗器械，化妆品
A32: 分为两种，一种是美国注册FDA,FILE FDA，，另一种是要生产厂商的FDA 注册号和产品的注册号。
A33: FILE FDA:
A34: 日用品：碗、锅、勺子叉子（户外烧烤刀叉可以不需要）、蛋糕模型、披萨盘模型、不锈钢刀、杯子、醒酒器、酒瓶、不锈钢冰块、烟灰缸，水瓶， 饭盒，杯子，瓶子，榨汁机。
A35: 化妆品：BB箱，睫毛膏，面膜
A37: FDA 认证: 食品，药品，大部分化妆品,医疗器械，电子烟及烟草，动物皮毛制品，成人用品，管制刀具，植物种子
A38: 常见FDA认证产品：
A39: 日用品：太阳镜，各种眼镜，急救包，陶瓷用品，电动牙刷，洗澡刷、电动牙刷、牙膏
A40: 美容仪器：面膜、眼膜、纹身针、化妆刷、
A41: 理疗产品：按摩器、性用品、温度计、
A42: 宠物用品：激光灯类、红外线类、猫薄荷、防潮剂
... A59: 蓝牙，HIMI等。

Sheet 反倾销目录
A1: 美国对华反倾销产品目录表 截止2016年1月1日
A2: 更多反倾销商品请登入网址查询：https://www.usitc.gov/trade_remedy/731_ad_701_cvd/investigations.htm | G2: 返回目录
A3: 以下反倾销的品名严格拒收
A4: 1、不锈钢货架
A5: 2、太阳能类
A6: 3、带线条笔记本
A7: 4、石蜡类 | D7: Current PRC-wide Rate | E7: Date of AD
A8: Order | B8: POR
A9: Jan.
A10: A-570-001 | B10: Potassium Permanganate | C10: 高锰酸钾 | D10: 1.2894 | E10: 1984.01.31 | F10: 01.01 - 12.31
A11: A-570-866 | B11: Folding Gift Boxes | C11: 折叠礼品盒 | D11: 1.6475 | E11: 2002.01.08 | F11: 01.01 - 12.31
A12: A-570-873 | B12: Ferrovanadium | C12: 铁钒合金 | D12: 0.6671 | E12: 2003.01.28 | F12: 01.01 - 12.31
A13: A-570-895 | B13: Crepe Paper | C13: 皱纹纸 | D13: 2.6683 | E13: 2005.01.25 | F13: 01.01 - 12.31
A14: A-570-890 | B14: Wooden Bedroom Furniture | C14: 木制卧室家具 | D14: 2.1601 | E14: 2005.01.04 | F14: 01.01 -12.31
A15: Feb.
A16: A-570-501 | B16: Natural Bristle Paintbrushes and Brush Heads | C16: 天然猪鬃油漆刷及刷头 | D16: 3.5192 | E16: 1986.02.14 | F16: 02.01 - 01.31
A17: A-570-803 | B17: Heavy Forged Hand Tools | C17: 重锻造手动工具 | D17: 斧子：174.58%; 撬杠：139.31%; 锤子：45.52%; 镐头：98.77% | E17: 1991.02.19 | F17: 02.01 - 01.31
A18: A-570-851 | B18: Preserved Mushrooms | C18: 淹渍蘑菇 | D18: 1.9863 | E18: 1997.02.19 | F18: 02.01 - 01.31
A19: A-570-893 | B19: Frozen and Canned Warmwater Shrimp | C19: 冷冻的和罐装的暖水虾 | D19: 1.1281 | E19: 2005.02.01 | F19: 02.01 - 01.31
A20: A-570-928 | B20: Uncovered Innerspring Units | C20: 非封闭内置弹簧部件 | D20: 2.3451 | E20: 2009.02.19 | F20: 02.01 - 01.31
A21: A-570-929 | B21: Small Diameter Graphite Electrodes | C21: 小直径石墨电极 | D21: 1.5964 | E21: 2009.02.26 | F21: 02.01 - 01.31
A22: A-570-981 | B22: Utility Scale Wind Towers | C22: 风塔 | D22: 0.7063 | E22: 2013.02.15 | F22: 02.01-01.31
A23: March
A24: A-570-002 | B24: Chloropicrin | C24: 三氯硝基甲烷 | D24: 0.58 | E24: 1984.03.22 | F24: 03.01 - 02.28
A25: A-570-836 | B25: Glycine | C25: 氨基乙酸.甘氨酸 | D25: 155.89% 453.79% | E25: 1995.03.29 | F25: 03.01 - 02.28
A26: A-570-894 | B26: Tissue Paper | C26: 薄页纸 | D26: 1.1264 | E26: 2005.03.30 | F26: 03.01 - 02.28
A27: A-570-908 | B27: Sodium Hexametaphosphate | C27: 六偏磷酸钠 | D27: 1.8805 | E27: 2008.03.19 | F27: 03.01 - 02.28
A28: A-570-930 | B28: Circular Welded Austenitic Stainless Pressure Pipe | C28: 圆形焊接奥氏体不锈高压套管 | D28: 0.5521 | E28: 2009.03.17 | F28: 03.01 - 02.28
A29: A-570-965 | B29: Drill Pipe | C29: 钻杆 | D29: 4.2995 | E29: 2011.03.03 | F29: 03.01 - 02.28
A30: A-570-973 | B30: Certain Steel Wheels | C30: 钢制轮毂 | D30: 1.9354 | E30: 2012.03.23
A31: A-570-975 | B31: Galvanized Steel Wire | C31: 镀锌钢丝 | D31: 2.35 | E31: 2012.03.26
A32: April
A33: A-570-867 | B33: Automotive Replacement Glass Windshields | C33: 汽车挡风玻璃 | D33: 1.245 | E33: 2002.04.04 | F33: 04.01-03.31
A34: A-570-875 | B34: Non-malleable Cast Iron Pipe Fittings | C34: 无可锻性铸铁管件 | D34: 0.755 | E34: 2003.04.07 | F34: 04.01 - 03.31
A35: A-570-896 | B35: Magnesium metal | C35: 镁金属 | D35: 1.4149 | E35: 2005.04.15 | F35: 04.01 - 03.31
A36: A-570-904 | B36: Certain Activated Carbon | C36: 活性碳 | D36: 2.2811 | E36: 2007.04.27 | F36: 04.01-03.31
A37: A-570-932 | B37: Steel Threaded Rod | C37: 钢制螺杆 | D37: 2.06 | E37: 2009.04.17 | F37: 04.01-03.31
A38: A-570-933 | B38: Frontseating Service Valves | C38: 空调用截止阀 | D38: 0.5562 | E38: 2009.04.28 | F38: 04.01-03.31
A39: A-570-934 | B39: 1-Hydroxyethylidene-1,1-Diphosphonic Acid (Hedp) | C39: 羟基亚乙基二膦酸 | D39: 0.7242 | E39: 2009.04.28 | F39: 04.01-03.31
A40: A-570-983 | B40: Drawn Stainless Steel Sinks | C40: 不锈钢拉制水槽 | D40: 0.7653 | E40: 2013.04.11 | F40: 04.01-03.31
...

Sheet FBA仓库地址表
A1: 美国亚马逊地址表
A2: Code | B2: State | C2: City | D2: Address1 | E2: Address2 | F2: Zip | G2: 返回目录
A3: PHX3 | B3: AZ | C3: Phoenix | D3: 6835 W. Buckeye Rd. | F3: 85043
A4: PHX5 | B4: AZ | C4: Goodyear | D4: 16920 W. Commerce Dr. | F4: 85338
A5: PHX6 | B5: AZ | C5: Phoenix | D5: 4750 W. Mohave St. | F5: 85043
A6: PHX7 | B6: AZ | C6: Phoenix | D6: 800 N. 75th Ave | F6: 85043
A7: TFC1 | B7: AZ | C7: Phoenix | D7: 4750 W. Mohave St | F7: 85043
A8: ONT2 | B8: CA | C8: San Bernardino | D8: 1910 E Central Ave. | F8: 92408
A9: ONT4 | B9: CA | C9: San Bernardino | D9: 1910 E Central Ave, | F9: 92408
A10: ONT5 | B10: CA | C10: San Bernardino | D10: 2020 E. Central Ave. | E10: Southgate Building 4 | F10: 924082606
A11: ONT6 | B11: CA | C11: Moreno Valley | D11: 24208 San Michele Rd. | F11: 92551
A12: ONT8 | B12: CA | C12: Moreno Valley | D12: 24300 Nandina Ave. | F12: 92551
A13: ONT9 | B13: CA | C13: Redlands | D13: 2125 W. San Bernardino Ave. | F13: 92374
A14: ORD6 | B14: IL | C14: Wood Dale | D14: 1250 N Mittel Blvd | F14: 60191
A15: SNA4 | B15: CA | C15: Rialto | D15: 2496 W Walnut Ave | F15: 923763009
A16: OAK3 | B16: CA | C16: Patterson | D16: 255 Park Center Drive. | F16: 953638876
A17: OAK4 | B17: CA | C17: Tracy | D17: 1555 N. Chrisman Rd. | F17: 95304
A18: OAK6 | B18: CA | C18: Tracy | D18: 1555 N. Chrisman Rd | F18: 95304
A19: OAK7 | B19: CA | C19: Newark | D19: 38811 Cherry St | F19: 94560
A20: SJC7 | B20: CA | C20: Tracy | D20: 188 Mountain House Pkwy. | F20: 95391
A21: SNA4 | B21: CA | C21: Rialto | D21: 2496 W Walnut Ave | F21: 923763009
A22: SNA6 | B22: CA | C22: Eastvale | D22: 5250 Goodman Road. | F22: 91752
A23: SNA7 | B23: CA | C23: San Bernadino | D23: 555 East Orange Show Rd, | F23: 92408
A24: SNA8 | B24: CA | C24: San Bernadino | D24: 555 East Orange Show Rd, | F24: 92408
A25: SNA9 | B25: CA | C25: Eastvale | D25: 5250 Goodman Road. | F25: 91752
A26: XUSD | B26: CA | C26: Stockton | D26: 1909 Zephyr St. | F26: 95206
A27: OAK5 | B27: CA | C27: Newark | D27: 3822 Cherry Street | F27: 94560
A28: MCI5 | B28: KS | C28: Lenexa | D28: 16851 W 113th St | F28: 66219
A29: MKC4 | B29: KS | C29: Edgerton | D29: 19645 Waverly Rd. | F29: 660219588
A30: TUL1 | B30: KS | C30: Coffeyville | D30: 2654 North Highway 169 | F30: 67337
A31: RNO2 | B31: NE | C31: Reno | D31: 8000 North Virginia Street | F31: 85906
A32: LAS2 | B32: NV | C32: Las Vegas | D32: 3837 Bay Lake Trail | E32: Suite 111 North | F32: 89030
A33: RNO1 | B33: NV | C33: Fernley | D33: 1600 East Newlands Drive | F33: 89408
A34: RNO4 | B34: NV | C34: Reno | D34: 8000 North Virginia Street | F34: 89506
A35: DFW1 | B35: TX | C35: Dallas | D35: 2700 Regent Blvd | F35: 75261
A36: DFW6 | B36: TX | C36: Coppell | D36: 940 W Bethel Road | F36: 75019
A37: DFW7 | B37: TX | C37: Fort Worth | D37: 700 Westport Parkway | F37: 76177
A38: DFW8 | B38: TX | C38: Dallas | D38: 2700 Regent Blvd | F38: 75261
A39: DFW9 | B39: TX | C39: Irving | D39: 2700 Regent Boulevard, | F39: 75063
